Workbook
Name BR_ANANTRAJ: '5Y_Price_Returns'!$Q$6:$Q$1203
Name BR_CNXREALTY: '5Y_Price_Returns'!$T$6:$T$1203
Name BR_NSEI: '5Y_Price_Returns'!$S$6:$S$1203
Name BR_OBEROIRLTY: '5Y_Price_Returns'!$P$6:$P$1203
Name BR_PHOENIXLTD: '5Y_Price_Returns'!$R$6:$R$1203
Name COVMAT: Correlation_Covariance!$B$14:$D$16
Name LR_ANANTRAJ: '5Y_Price_Returns'!$J$7:$J$1245
Name LR_CNXREALTY: '5Y_Price_Returns'!$M$7:$M$1216
Name LR_NSEI: '5Y_Price_Returns'!$L$7:$L$1245
Name LR_OBEROIRLTY: '5Y_Price_Returns'!$I$7:$I$1245
Name LR_PHOENIXLTD: '5Y_Price_Returns'!$K$7:$K$1245
Name MU: Portfolio_Optimization!$B$8:$D$8
Name PX_ANANTRAJ: '5Y_Price_Returns'!$C$6:$C$1245
Name PX_CNXREALTY: '5Y_Price_Returns'!$F$6:$F$1245
Name PX_NSEI: '5Y_Price_Returns'!$E$6:$E$1245
Name PX_OBEROIRLTY: '5Y_Price_Returns'!$B$6:$B$1245
Name PX_PHOENIXLTD: '5Y_Price_Returns'!$D$6:$D$1245
Name Rf: Risk_Return_Metrics!$B$4
Name TDays: Risk_Return_Metrics!$D$4
Name Yrs: Risk_Return_Metrics!$F$4

Sheet Executive Summary & Recos
A1: INDIAN REAL ESTATE — 3-STOCK PORTFOLIO · EXECUTIVE SUMMARY & RECOMMENDATIONS
A3: Analysis window 2021-08-23 to 2026-08-27 (5.01 years) · Rf 6.80% · Universe 10 listed developers · Prepared 2026-08-30
A5: SELECTED HOLDINGS
A6: Archetype | B6: Company | C6: Ticker | D6: 5Y CAGR | E6: Ann. σ | F6: Sharpe | G6: Beta (Realty) | H6: Max DD
A7: The Balance-Sheet Fortress | B7: Oberoi Realty | C7: OBEROIRLTY.NS | D7: =Risk_Return_Metrics!B10 -> 0.23571047 | E7: =Risk_Return_Metrics!B12 -> 0.3417008 | F7: =Risk_Return_Metrics!B13 -> 0.49081087 | G7: =Risk_Return_Metrics!B14 -> 0.95161831 | H7: -0.3886199
A8: The High-Velocity Growth Engine | B8: Anant Raj Ltd | C8: ANANTRAJ.NS | D8: =Risk_Return_Metrics!C10 -> 0.59802199 | E8: =Risk_Return_Metrics!C12 -> 0.50278037 | F8: =Risk_Return_Metrics!C13 -> 1.0541819 | G8: =Risk_Return_Metrics!C14 -> 0.91844177 | H8: -0.56582934
A9: The Annuity / Commercial Cash-Flow Champion | B9: Phoenix Mills | C9: PHOENIXLTD.NS | D9: =Risk_Return_Metrics!D10 -> 0.36619517 | E9: =Risk_Return_Metrics!D12 -> 0.35630744 | F9: =Risk_Return_Metrics!D13 -> 0.83690414 | G9: =Risk_Return_Metrics!D14 -> 0.70896333 | H9: -0.31631136
A11: CLIENT A vs CLIENT B — SIDE-BY-SIDE KPI COMPARISON
A12: KPI | B12: Client A (Risk-Averse) | C12: Client B (Risk-Seeker) | D12: Delta (B − A)
A13: Mandate | B13: Capital preservation, low volatility | C13: Capital appreciation, momentum | D13: —
A14: Optimisation objective | B14: Minimum variance | C14: Growth-weighted maximum Sharpe | D14: —
A15: Weight · Oberoi Realty | B15: =Portfolio_Optimization!B14 -> 0.45 | C15: =Portfolio_Optimization!B21 -> 0.125941 | D15: =C15-B15 -> -0.324059
A16: Weight · Anant Raj Ltd | B16: =Portfolio_Optimization!C14 -> 0.109393 | C16: =Portfolio_Optimization!C21 -> 0.4 | D16: =C16-B16 -> 0.290607
A17: Weight · Phoenix Mills | B17: =Portfolio_Optimization!D14 -> 0.440607 | C17: =Portfolio_Optimization!D21 -> 0.474059 | D17: =C17-B17 -> 0.033452
A18: Expected return μp | B18: =Portfolio_Optimization!B27 -> 0.35969272 | C18: =Portfolio_Optimization!B41 -> 0.42548586 | D18: =C18-B18 -> 0.065793144
A19: Volatility σp | B19: =Portfolio_Optimization!B31 -> 0.27903461 | C19: =Portfolio_Optimization!B45 -> 0.3149159 | D19: =C19-B19 -> 0.035881288
A20: Sharpe ratio | B20: =Portfolio_Optimization!B32 -> 1.0453639 | C20: =Portfolio_Optimization!B46 -> 1.1351788 | D20: =C20-B20 -> 0.089814898
A21: Sortino ratio | B21: =Portfolio_Optimization!B38 -> 1.5414701 | C21: =Portfolio_Optimization!B52 -> 1.6569743 | D21: =C21-B21 -> 0.11550417
A22: Max drawdown (5Y actual) | B22: =Portfolio_Optimization!B36 -> -0.30574177 | C22: =Portfolio_Optimization!B50 -> -0.36061405 | D22: =C22-B22 -> -0.054872287
A23: Portfolio beta vs Realty | B23: =Portfolio_Optimization!B33 -> 0.84107355 | C23: =Portfolio_Optimization!B47 -> 0.82331492 | D23: =C23-B23 -> -0.017758629
A24: Daily VaR 95% | B24: =Portfolio_Optimization!B37 -> -0.027204763 | C24: =Portfolio_Optimization!B51 -> -0.030274748 | D24: =C24-B24 -> -0.0030699853
A25: Diversification ratio | B25: =Portfolio_Optimization!B35 -> 1.3107964 | C25: =Portfolio_Optimization!B49 -> 1.3116424 | D25: =C25-B25 -> 0.00084597461
A27: ACTIONABLE RECOMMENDATION — CLIENT A (RISK-AVERSE)
A28: Allocation | B28: Oberoi Realty / Anant Raj Ltd / Phoenix Mills = 45% / 11% / 44%. Anchored on the minimum-variance solution, which is independent of the expected-return estimate and therefore the most robust allocation available.
A29: Entry strategy | B29: Staggered entry — deploy in 4 equal monthly tranches over 4 months (25% each). The portfolio has drawn down 30%+ inside the study window, so averaging in materially reduces single-point entry risk. Accelerate the remaining tranches if the Nifty Realty index falls more than 10% from the entry reference.
A30: Holding period | B30: Minimum 3 years, target 5 years. Annuity and low-leverage names compound through cycles; shorter horizons expose the client to sector beta they are not being paid to take.
A31: Target yield | B31: Base case 36.0% p.a. on shrunk inputs. Plan against a normalised 12–15% p.a. total return; treat anything above that as cycle-driven upside, not entitlement.
A32: Downside protection | B32: Portfolio σ of 27.9% is the lowest attainable from these three assets under the 10–45% bounds, and 24% below the weighted-average standalone σ. Worst observed drawdown -30.6%.
A33: Stop-loss discipline | B33: No hard price stop (forced selling in a cyclical sector destroys value). Instead use a fundamental stop: exit if consolidated net D/E exceeds 1.0x, or if two consecutive quarters show negative operating cash flow at any holding.
A35: ACTIONABLE RECOMMENDATION — CLIENT B (RISK-SEEKER)
A36: Allocation | B36: Oberoi Realty / Anant Raj Ltd / Phoenix Mills = 13% / 40% / 47%. Growth-weighted max-Sharpe with a hard 40% floor in Anant Raj Ltd, the fastest-compounding name in the universe.
A37: Entry strategy | B37: Front-loaded — 60% lump sum immediately to capture momentum, 40% held for two tranches deployed on 5% and 10% drawdowns from entry. Momentum strategies decay when entry is over-diluted, but a reserve tranche preserves the ability to average into volatility.
A38: Holding period | B38: 3–5 years with active review. This sleeve is explicitly cycle-levered; the exit decision is a function of the rate cycle and pre-sales momentum, not the calendar.
A39: Target yield | B39: Base case 42.5% p.a. on shrunk inputs, versus 36.0% for Client A — roughly 70bps of excess return for 400bps of extra volatility.
A40: Upside catalysts | B40: Rate-cut transmission into home-loan rates, pre-sales beats, land-bank monetisation and new launches, REIT/InvIT monetisation of commercial assets, and index inclusion driving passive flows.
A41: Stop-loss discipline | B41: Position-level trailing stop of 25% from the running peak on the growth sleeve (Anant Raj Ltd) only, given its 50% volatility and mid-cap liquidity profile. Hard review trigger if quarterly pre-sales growth turns negative.
A43: PORTFOLIO GOVERNANCE & REBALANCING TRIGGERS
A44: Calendar rebalance | B44: Semi-annual review; rebalance only if a weight has drifted more than 500bps from target (avoids churn and short-term capital-gains drag).
A45: Drift trigger | B45: Hard rebalance if any single holding exceeds 50% of portfolio value, or falls below 5%.
A46: Macro trigger | B46: Rebalance toward Client A weights if the RBI raises the repo rate by more than 50bps cumulatively, or if the 10Y G-Sec yield rises above 7.5% — real estate is the most rate-sensitive sector on the exchange.
...

Sheet 5Y_Price_Returns
A1: 5-YEAR DAILY PRICE SERIES, LOG RETURNS & MONTHLY AGGREGATES
A3: Adjusted closes (splits/dividends). 2021-08-23 to 2026-08-27 · 1240 sessions · Source: Yahoo Finance via yfinance
O4: REALTY-ALIGNED RETURN BLOCK (gap-free pairs for beta / correlation)
A5: Date | B5: Oberoi Realty (OBEROIRLTY.NS) | C5: Anant Raj Ltd (ANANTRAJ.NS) | D5: Phoenix Mills (PHOENIXLTD.NS) | E5: ^NSEI | F5: ^CNXREALTY | I5: ln(Pt/Pt-1) OBEROIRLTY | J5: ln(Pt/Pt-1) ANANTRAJ | K5: ln(Pt/Pt-1) PHOENIXLTD | L5: ln ^NSEI | M5: ln ^CNXREALTY | O5: Aligned date | P5: OBEROIRLTY aligned | Q5: ANANTRAJ aligned | R5: PHOENIXLTD aligned | S5: ^NSEI aligned | T5: ^CNXREALTY aligned | V5: Month End | W5: OBEROIRLTY monthly % | X5: ANANTRAJ monthly % | Y5: PHOENIXLTD monthly % | Z5: ^NSEI monthly % | AA5: ^CNXREALTY monthly %
A6: 44431 | B6: 648.61542 | C6: 57.800404 | D6: 398.27859 | E6: 16496.449 | F6: 369.70001 | O6: 44432 | P6: =I7 -> 0.014723322 | Q6: =J7 -> -0.023367617 | R6: =K7 -> 0.032448485 | S6: =L7 -> 0.0077383437 | T6: =M7 -> 0.01809337 | V6: 44469 | W6: 0.37038073 | X6: 0.17762651 | Y6: 0.11222296 | Z6: 0.028364786 | AA6: 0.32833507
A7: 44432 | B7: 658.23584 | C7: 56.465405 | D7: 411.41409 | E7: 16624.6 | F7: 376.45001 | I7: =LN(B7/B6) -> 0.014723322 | J7: =LN(C7/C6) -> -0.023367617 | K7: =LN(D7/D6) -> 0.032448485 | L7: =LN(E7/E6) -> 0.0077383437 | M7: =LN(F7/F6) -> 0.01809337 | O7: 44433 | P7: =I8 -> 0.0021491029 | Q7: =J8 -> 0.0061109072 | R7: =K8 -> 0.023575318 | S7: =L8 -> 0.00060439015 | T7: =M8 -> -0.0078672641 | V7: 44500 | W7: -0.061086879 | X7: -0.19367587 | Y7: 0.0058427712 | Z7: 0.0030366411 | AA7: -0.02938882
A8: 44433 | B8: 659.65198 | C8: 56.811516 | D8: 421.22855 | E8: 16634.65 | F8: 373.5 | I8: =LN(B8/B7) -> 0.0021491029 | J8: =LN(C8/C7) -> 0.0061109072 | K8: =LN(D8/D7) -> 0.023575318 | L8: =LN(E8/E7) -> 0.00060439015 | M8: =LN(F8/F7) -> -0.0078672641 | O8: 44434 | P8: =I9 -> -0.01439106 | Q8: =J9 -> 0.048417086 | R8: =K9 -> 0.013093533 | S8: =L9 -> 0.00013525068 | T8: =M9 -> 0.0026737984 | V8: 44530 | W8: -0.080139075 | X8: 0.064542479 | Y8: -0.016804174 | Z8: -0.038957944 | AA8: -0.022257882
A9: 44434 | B9: 650.22687 | C9: 59.629841 | D9: 426.78018 | E9: 16636.9 | F9: 374.5 | I9: =LN(B9/B8) -> -0.01439106 | J9: =LN(C9/C8) -> 0.048417086 | K9: =LN(D9/D8) -> 0.013093533 | L9: =LN(E9/E8) -> 0.00013525068 | M9: =LN(F9/F8) -> 0.0026737984 | O9: 44435 | P9: =I10 -> 0.018675459 | Q9: =J10 -> 0.040622939 | R9: =K10 -> -0.0069345963 | S9: =L10 -> 0.004096858 | T9: =M10 -> 0.0073162947 | V9: 44561 | W9: 0.034884305 | X9: 0.18726015 | Y9: 0.039563281 | Z9: 0.021836378 | AA9: -0.0070754966
A10: 44435 | B10: 662.48425 | C10: 62.102055 | D10: 423.83087 | E10: 16705.199 | F10: 377.25 | I10: =LN(B10/B9) -> 0.018675459 | J10: =LN(C10/C9) -> 0.040622939 | K10: =LN(D10/D9) -> -0.0069345963 | L10: =LN(E10/E9) -> 0.004096858 | M10: =LN(F10/F9) -> 0.0073162947 | O10: 44438 | P10: =I11 -> 0.028915893 | Q10: =J11 -> 0.048183495 | R10: =K11 -> 0.017907774 | S10: =L11 -> 0.013429259 | T10: =M11 -> 0.01916569 | V10: 44592 | W10: 0.062659489 | X10: 0.054298763 | Y10: 0.010706984 | Z10: -0.00081832029 | AA10: -0.0080553422
A11: 44438 | B11: 681.92023 | C11: 65.16761 | D11: 431.48911 | E11: 16931.051 | F11: 384.54999 | I11: =LN(B11/B10) -> 0.028915893 | J11: =LN(C11/C10) -> 0.048183495 | K11: =LN(D11/D10) -> 0.017907774 | L11: =LN(E11/E10) -> 0.013429259 | M11: =LN(F11/F10) -> 0.01916569 | O11: 44439 | P11: =I12 -> 0.0077045354 | Q11: =J12 -> -0.020698364 | R11: =K12 -> -0.008942738 | S11: =L12 -> 0.011810428 | T11: =M12 -> 0.0058339443 | V11: 44620 | W11: -0.0093905597 | X11: -0.10239136 | Y11: -0.037001751 | Z11: -0.031485234 | AA11: -0.091306624
A12: 44439 | B12: 687.1944 | C12: 63.832611 | D12: 427.64761 | E12: 17132.199 | F12: 386.79999 | I12: =LN(B12/B11) -> 0.0077045354 | J12: =LN(C12/C11) -> -0.020698364 | K12: =LN(D12/D11) -> -0.008942738 | L12: =LN(E12/E11) -> 0.011810428 | M12: =LN(F12/F11) -> 0.0058339443 | O12: 44440 | P12: =I13 -> 0.10122309 | Q12: =J13 -> -0.010120702 | R12: =K13 -> 0.043491194 | S12: =L13 -> -0.0032710789 | T12: =M13 -> 0.054216933 | V12: 44651 | W12: 0.035989815 | X12: -0.099726761 | Y12: 0.14691617 | Z12: 0.039946028 | AA12: 0.062213552
A13: 44440 | B13: 760.39673 | C13: 63.189838 | D13: 446.65689 | E13: 17076.25 | F13: 408.35001 | I13: =LN(B13/B12) -> 0.10122309 | J13: =LN(C13/C12) -> -0.010120702 | K13: =LN(D13/D12) -> 0.043491194 | L13: =LN(E13/E12) -> -0.0032710789 | M13: =LN(F13/F12) -> 0.054216933 | O13: 44441 | P13: =I14 -> -0.029127389 | Q13: =J14 -> 0.019372748 | R13: =K14 -> -0.0027225368 | S13: =L14 -> 0.009204294 | T13: =M14 -> 0.012411953 | V13: 44681 | W13: 0.021705567 | X13: -0.043247327 | Y13: -0.012273334 | Z13: -0.020738872 | AA13: -0.042713814
A14: 44441 | B14: 738.56781 | C14: 64.425934 | D14: 445.4425 | E14: 17234.15 | F14: 413.45001 | I14: =LN(B14/B13) -> -0.029127389 | J14: =LN(C14/C13) -> 0.019372748 | K14: =LN(D14/D13) -> -0.0027225368 | L14: =LN(E14/E13) -> 0.009204294 | M14: =LN(F14/F13) -> 0.012411953 | O14: 44442 | P14: =I15 -> 0.0083623072 | Q14: =J15 -> -0.024865189 | R14: =K15 -> -0.025470476 | S14: =L15 -> 0.005176808 | T14: =M15 -> 0.010585913 | V14: 44712 | W14: -0.16089562 | X14: -0.1490879 | Y14: 0.074048565 | Z14: -0.03028788 | AA14: -0.072225325
A15: 44442 | B15: 744.76984 | C15: 62.843723 | D15: 434.24014 | E15: 17323.6 | F15: 417.85001 | I15: =LN(B15/B14) -> 0.0083623072 | J15: =LN(C15/C14) -> -0.024865189 | K15: =LN(D15/D14) -> -0.025470476 | L15: =LN(E15/E14) -> 0.005176808 | M15: =LN(F15/F14) -> 0.010585913 | O15: 44445 | P15: =I16 -> 0.070071959 | Q15: =J16 -> 0.035552466 | R15: =K16 -> -0.0054368499 | S15: =L16 -> 0.0031238633 | T15: =M16 -> 0.031101533 | V15: 44742 | W15: -0.084517397 | X15: -0.048462406 | Y15: 0.014397025 | Z15: -0.048496989 | AA15: -0.06412442
A16: 44445 | B16: 798.82922 | C16: 65.118164 | D16: 431.88565 | E16: 17377.801 | F16: 431.04999 | I16: =LN(B16/B15) -> 0.070071959 | J16: =LN(C16/C15) -> 0.035552466 | K16: =LN(D16/D15) -> -0.0054368499 | L16: =LN(E16/E15) -> 0.0031238633 | M16: =LN(F16/F15) -> 0.031101533 | O16: 44446 | P16: =I17 -> -0.032494416 | Q16: =J17 -> 0.013574895 | R16: =K17 -> -0.0017230742 | S16: =L17 -> -0.00090392734 | T16: =M17 -> -0.023591231 | V16: 44773 | W16: 0.23858998 | X16: 0.4510111 | Y16: 0.059390176 | Z16: 0.087324345 | AA16: 0.17038678
A17: 44446 | B17: 773.28894 | C17: 66.008163 | D17: 431.14212 | E17: 17362.1 | F17: 421 | I17: =LN(B17/B16) -> -0.032494416 | J17: =LN(C17/C16) -> 0.013574895 | K17: =LN(D17/D16) -> -0.0017230742 | L17: =LN(E17/E16) -> -0.00090392734 | M17: =LN(F17/F16) -> -0.023591231 | O17: 44447 | P17: =I18 -> -0.022415228 | Q17: =J18 -> 0.047540971 | R17: =K18 -> 0.0022967496 | S17: =L18 -> -0.000495432 | T17: =M18 -> -0.00071281407 | V17: 44804 | W17: 0.10624642 | X17: 0.17997302 | Y17: 0.12161074 | Z17: 0.035029842 | AA17: 0.027164873
A18: 44447 | B18: 756.14832 | C18: 69.222046 | D18: 432.13348 | E18: 17353.5 | F18: 420.70001 | I18: =LN(B18/B17) -> -0.022415228 | J18: =LN(C18/C17) -> 0.047540971 | K18: =LN(D18/D17) -> 0.0022967496 | L18: =LN(E18/E17) -> -0.000495432 | M18: =LN(F18/F17) -> -0.00071281407 | O18: 44448 | P18: =I19 -> -0.00051697415 | Q18: =J19 -> 0.015592112 | R18: =K19 -> 0.0016618775 | S18: =L19 -> 0.00090718627 | T18: =M19 -> -0.0073959684 | V18: 44834 | W18: -0.088444158 | X18: 0.11295879 | Y18: -0.0035480556 | Z18: -0.037442418 | AA18: -0.084628694
... A64: 44516 | B64: 947.43152 | C64: 67.049736 | D64: 532.41144 | E64: 17999.199 | F64: 545.09998 | I64: =LN(B64/B63) -> 0.0073979785 | J64: =LN(C64/C63) -> -0.023358852 | K64: =LN(D64/D63) -> -0.044036489 | L64: =LN(E64/E63) -> -0.0061065893 | M64: =LN(F64/F63) -> -0.0013749487 | O64: 44517 | P64: =I65 -> -0.013178559 | Q64: =J65 -> 0.00073820569 | R64: =K65 -> 0.010846691 | S64: =L65 -> -0.0056019562 | T64: =M65 -> -0.016555201 | V64: 46234 | W64: 0.034182943 | X64: 0.2000502 | Y64: -0.028379312 | Z64: 0.021698443 | AA64: 0.10746794
A65: 44517 | B65: 935.02765 | C65: 67.099251 | D65: 538.21777 | E65: 17898.65 | F65: 536.15002 | I65: =LN(B65/B64) -> -0.013178559 | J65: =LN(C65/C64) -> 0.00073820569 | K65: =LN(D65/D64) -> 0.010846691 | L65: =LN(E65/E64) -> -0.0056019562 | M65: =LN(F65/F64) -> -0.016555201 | O65: 44518 | P65: =I66 -> -0.038166281 | Q65: =J66 -> -0.0036968324 | R65: =K66 -> -0.0025851698 | S65: =L66 -> -0.0075062975 | T65: =M66 -> -0.017403195 | V65: 46265 | W65: 0.024730576 | X65: -0.03082466 | Y65: 0.0044366461 | Z65: -0.012006021
A66: 44518 | B66: 900.01355 | C66: 66.851654 | D66: 536.82819 | E66: 17764.801 | F66: 526.90002 | I66: =LN(B66/B65) -> -0.038166281 | J66: =LN(C66/C65) -> -0.0036968324 | K66: =LN(D66/D65) -> -0.0025851698 | L66: =LN(E66/E65) -> -0.0075062975 | M66: =LN(F66/F65) -> -0.017403195 | O66: 44522 | P66: =I67 -> -0.038383186 | Q66: =J67 -> -0.040050622 | R66: =K67 -> -0.072647714 | S66: =L67 -> -0.019798067 | T66: =M67 -> -0.042254382
A67: 44522 | B67: 866.12274 | C67: 64.227112 | D67: 499.21176 | E67: 17416.551 | F67: 505.10001 | I67: =LN(B67/B66) -> -0.038383186 | J67: =LN(C67/C66) -> -0.040050622 | K67: =LN(D67/D66) -> -0.072647714 | L67: =LN(E67/E66) -> -0.019798067 | M67: =LN(F67/F66) -> -0.042254382 | O67: 44523 | P67: =I68 -> 0.0032086745 | Q67: =J68 -> 0.0015406776 | R67: =K68 -> 0.03975783 | S67: =L68 -> 0.0049713204 | T67: =M68 -> 0.021350324 | V67: Monthly returns are simple month-end-to-month-end changes; daily returns above are logarithmic.
A68: 44523 | B68: 868.90631 | C68: 64.326141 | D68: 519.45917 | E68: 17503.35 | F68: 516 | I68: =LN(B68/B67) -> 0.0032086745 | J68: =LN(C68/C67) -> 0.0015406776 | K68: =LN(D68/D67) -> 0.03975783 | L68: =LN(E68/E67) -> 0.0049713204 | M68: =LN(F68/F67) -> 0.021350324 | O68: 44524 | P68: =I69 -> -0.012214008 | Q68: =J69 -> 0.048093564 | R68: =K69 -> -0.010854011 | S68: =L69 -> -0.0050574491 | T68: =M69 -> -0.00067847737
A69: 44524 | B69: 858.35803 | C69: 67.495415 | D69: 513.85144 | E69: 17415.051 | F69: 515.65002 | I69: =LN(B69/B68) -> -0.012214008 | J69: =LN(C69/C68) -> 0.048093564 | K69: =LN(D69/D68) -> -0.010854011 | L69: =LN(E69/E68) -> -0.0050574491 | M69: =LN(F69/F68) -> -0.00067847737 | O69: 44525 | P69: =I70 -> 0.0013645339 | Q69: =J70 -> 0.045185159 | R69: =K70 -> 0.010997347 | S69: =L70 -> 0.0069353473 | T69: =M70 -> 0.019302443
A70: 44525 | B70: 859.53009 | C70: 70.615158 | D70: 519.53363 | E70: 17536.25 | F70: 525.70001 | I70: =LN(B70/B69) -> 0.0013645339 | J70: =LN(C70/C69) -> 0.045185159 | K70: =LN(D70/D69) -> 0.010997347 | L70: =LN(E70/E69) -> 0.0069353473 | M70: =LN(F70/F69) -> 0.019302443 | O70: 44526 | P70: =I71 -> -0.047470035 | Q70: =J71 -> -0.051071947 | R70: =K71 -> -0.077995145 | S70: =L71 -> -0.029502196 | T70: =M71 -> -0.064627344
A71: 44526 | B71: 819.68146 | C71: 67.099251 | D71: 480.55246 | E71: 17026.449 | F71: 492.79999 | I71: =LN(B71/B70) -> -0.047470035 | J71: =LN(C71/C70) -> -0.051071947 | K71: =LN(D71/D70) -> -0.077995145 | L71: =LN(E71/E70) -> -0.029502196 | M71: =LN(F71/F70) -> -0.064627344 | O71: 44529 | P71: =I72 -> -0.013495386 | Q71: =J72 -> -0.03072545 | R71: =K72 -> -0.033978127 | S71: =L72 -> 0.0016138312 | T71: =M72 -> -0.016779566
A72: 44529 | B72: 808.69385 | C72: 65.068947 | D72: 464.49847 | E72: 17053.949 | F72: 484.60001 | I72: =LN(B72/B71) -> -0.013495386 | J72: =LN(C72/C71) -> -0.03072545 | K72: =LN(D72/D71) -> -0.033978127 | L72: =LN(E72/E71) -> 0.0016138312 | M72: =LN(F72/F71) -> -0.016779566 | O72: 44530 | P72: =I73 -> 0.0057202921 | Q72: =J73 -> -0.0084066013 | R72: =K73 -> 0.012580734 | S72: =L73 -> -0.0041572285 | T72: =M73 -> 0.0061715891
A73: 44530 | B73: 813.33307 | C73: 64.524231 | D73: 470.37912 | E73: 16983.199 | F73: 487.60001 | I73: =LN(B73/B72) -> 0.0057202921 | J73: =LN(C73/C72) -> -0.0084066013 | K73: =LN(D73/D72) -> 0.012580734 | L73: =LN(E73/E72) -> -0.0041572285 | M73: =LN(F73/F72) -> 0.0061715891 | O73: 44531 | P73: =I74 -> 0.0047917943 | Q73: =J74 -> -0.0061586959 | R73: =K74 -> 0.025416803 | S73: =L74 -> 0.01075856 | T73: =M74 -> 0.014355019
A74: 44531 | B74: 817.23975 | C74: 64.128067 | D74: 482.48788 | E74: 17166.9 | F74: 494.64999 | I74: =LN(B74/B73) -> 0.0047917943 | J74: =LN(C74/C73) -> -0.0061586959 | K74: =LN(D74/D73) -> 0.025416803 | L74: =LN(E74/E73) -> 0.01075856 | M74: =LN(F74/F73) -> 0.014355019 | O74: 44532 | P74: =I75 -> 0.015240132 | Q74: =J75 -> 0.037139669 | R74: =K75 -> 0.020110135 | S74: =L75 -> 0.013581918 | T74: =M75 -> 0.0054435864
A75: 44532 | B75: 829.78998 | C75: 66.554543 | D75: 492.289 | E75: 17401.65 | F75: 497.35001 | I75: =LN(B75/B74) -> 0.015240132 | J75: =LN(C75/C74) -> 0.037139669 | K75: =LN(D75/D74) -> 0.020110135 | L75: =LN(E75/E74) -> 0.013581918 | M75: =LN(F75/F74) -> 0.0054435864 | O75: 44533 | P75: =I76 -> 0.0063943861 | Q75: =J76 -> -0.01348338 | R75: =K76 -> 5.0335575e-05 | S75: =L76 -> -0.011847592 | T75: =M76 -> -0.0021134579
A76: 44533 | B76: 835.11298 | C76: 65.663185 | D76: 492.31378 | E76: 17196.699 | F76: 496.29999 | I76: =LN(B76/B75) -> 0.0063943861 | J76: =LN(C76/C75) -> -0.01348338 | K76: =LN(D76/D75) -> 5.0335575e-05 | L76: =LN(E76/E75) -> -0.011847592 | M76: =LN(F76/F75) -> -0.0021134579 | O76: 44536 | P76: =I77 -> -0.015379873 | Q76: =J77 -> 0.048574553 | R76: =K77 -> 0.0023157322 | S76: =L77 -> -0.016679248 | T76: =M77 -> -0.013796096
A77: 44536 | B77: 822.36731 | C77: 68.93148 | D77: 493.45517 | E77: 16912.25 | F77: 489.5 | I77: =LN(B77/B76) -> -0.015379873 | J77: =LN(C77/C76) -> 0.048574553 | K77: =LN(D77/D76) -> 0.0023157322 | L77: =LN(E77/E76) -> -0.016679248 | M77: =LN(F77/F76) -> -0.013796096 | O77: 44537 | P77: =I78 -> 0.026660433 | Q77: =J78 -> 0.048379681 | R77: =K78 -> 0.03357303 | S77: =L78 -> 0.015515557 | T77: =M78 -> 0.022123256
A78: 44537 | B78: 844.58685 | C78: 72.348351 | D78: 510.30319 | E78: 17176.699 | F78: 500.45001 | I78: =LN(B78/B77) -> 0.026660433 | J78: =LN(C78/C77) -> 0.048379681 | K78: =LN(D78/D77) -> 0.03357303 | L78: =LN(E78/E77) -> 0.015515557 | M78: =LN(F78/F77) -> 0.022123256 | O78: 44538 | P78: =I79 -> 0.016799552 | Q78: =J79 -> 0.046800018 | R78: =K79 -> 0.037272026 | S78: =L79 -> 0.016917045 | T78: =M79 -> 0.017038502
A79: 44538 | B79: 858.89539 | C79: 75.814735 | D79: 529.68213 | E79: 17469.75 | F79: 509.04999 | I79: =LN(B79/B78) -> 0.016799552 | J79: =LN(C79/C78) -> 0.046800018 | K79: =LN(D79/D78) -> 0.037272026 | L79: =LN(E79/E78) -> 0.016917045 | M79: =LN(F79/F78) -> 0.017038502 | O79: 44539 | P79: =I80 -> -0.0030750446 | Q79: =J80 -> -0.015800334 | R79: =K80 -> -0.046111928 | S79: =L80 -> 0.0026924387 | T79: =M80 -> -0.0027539978
... A338: 44917 | B338: 837.14447 | C338: 100.76194 | D338: 673.36542 | E338: 18127.35 | F338: 424.5 | I338: =LN(B338/B337) -> -0.0109487 | J338: =LN(C338/C337) -> -0.036754632 | K338: =LN(D338/D337) -> -0.021364059 | L338: =LN(E338/E337) -> -0.0039502949 | M338: =LN(F338/F337) -> -0.014267593 | O338: 44918 | P338: =I339 -> -0.044238968 | Q338: =J339 -> -0.12136083 | R338: =K339 -> -0.034205752 | S338: =L339 -> -0.017841375 | T338: =M339 -> -0.035120752
A339: 44918 | B339: 800.9173 | C339: 89.246292 | D339: 650.72192 | E339: 17806.801 | F339: 409.85001 | I339: =LN(B339/B338) -> -0.044238968 | J339: =LN(C339/C338) -> -0.12136083 | K339: =LN(D339/D338) -> -0.034205752 | L339: =LN(E339/E338) -> -0.017841375 | M339: =LN(F339/F338) -> -0.035120752 | O339: 44923 | P339: =I342 -> 0.0034227873 | Q339: =J342 -> 0.024667879 | R339: =K342 -> 0.0012303677 | S339: =L342 -> -0.00054066117 | T339: =M342 -> 0.004928445
A340: 44921 | B340: 816.75128 | C340: 94.408478 | D340: 657.97974 | E340: 18014.6 | I340: =LN(B340/B339) -> 0.019576927 | J340: =LN(C340/C339) -> 0.056231001 | K340: =LN(D340/D339) -> 0.011091736 | L340: =LN(E340/E339) -> 0.011602068 | O340: 44924 | P340: =I343 -> 0.00053001054 | Q340: =J343 -> 0.045683217 | R340: =K343 -> 0.0022757324 | S340: =L343 -> 0.0037727061 | T340: =M343 -> 0.0014036875
A341: 44922 | B341: 829.30084 | C341: 97.386658 | D341: 686.43951 | E341: 18132.301 | F341: 425.04999 | I341: =LN(B341/B340) -> 0.015248367 | J341: =LN(C341/C340) -> 0.031058341 | K341: =LN(D341/D340) -> 0.042343979 | L341: =LN(E341/E340) -> 0.0065124028 | O341: 44925 | P341: =I344 -> 0.021839263 | Q341: =J344 -> 0.063052895 | R341: =K344 -> 0.026210515 | S341: =L344 -> -0.00472221 | T341: =M344 -> 0.009423577
A342: 44923 | B342: 832.14423 | C342: 99.818855 | D342: 687.28461 | E342: 18122.5 | F342: 427.14999 | I342: =LN(B342/B341) -> 0.0034227873 | J342: =LN(C342/C341) -> 0.024667879 | K342: =LN(D342/D341) -> 0.0012303677 | L342: =LN(E342/E341) -> -0.00054066117 | M342: =LN(F342/F341) -> 0.004928445 | O342: 44928 | P342: =I345 -> 0.0043113674 | Q342: =J345 -> -0.034024681 | R342: =K345 -> 0.0023521727 | S342: =L345 -> 0.0050766752 | T342: =M345 -> 0.009909099
A343: 44924 | B343: 832.58539 | C343: 104.48466 | D343: 688.85046 | E343: 18191 | F343: 427.75 | I343: =LN(B343/B342) -> 0.00053001054 | J343: =LN(C343/C342) -> 0.045683217 | K343: =LN(D343/D342) -> 0.0022757324 | L343: =LN(E343/E342) -> 0.0037727061 | M343: =LN(F343/F342) -> 0.0014036875 | O343: 44929 | P343: =I346 -> 0.0062324895 | Q343: =J346 -> 0.0073564174 | R343: =K346 -> 0.0037451087 | S343: =L346 -> 0.0019270696 | T343: =M346 -> 0.001260356
A344: 44925 | B344: 850.96844 | C344: 111.28486 | D344: 707.14429 | E344: 18105.301 | F344: 431.79999 | I344: =LN(B344/B343) -> 0.021839263 | J344: =LN(C344/C343) -> 0.063052895 | K344: =LN(D344/D343) -> 0.026210515 | L344: =LN(E344/E343) -> -0.00472221 | M344: =LN(F344/F343) -> 0.009423577 | O344: 44930 | P344: =I347 -> -0.019513068 | Q344: =J347 -> 0.019506339 | R344: =K347 -> -0.020470768 | S344: =L347 -> -0.010453518 | T344: =M347 -> -0.020709901
...

Sheet Risk_Return_Metrics
A1: RISK & RETURN METRICS — 5 YEAR
A3: All cells are live formulas driving off '5Y_Price_Returns'. Rf = 6.80% (RBI 10Y G-Sec / 91-day T-bill baseline). Annualisation factor = 252 trading days.
A4: Risk-free rate (Rf) | B4: 0.068 | C4: Trading days | D4: 252 | E4: Years in window (stocks) | F4: 5.0102669
A6: Metric | B6: Oberoi Realty | C6: Anant Raj Ltd | D6: Phoenix Mills | E6: NSEI | F6: CNXREALTY
A7: Initial price P_initial | B7: =INDEX(PX_OBEROIRLTY,1) -> 648.61542 | C7: =INDEX(PX_ANANTRAJ,1) -> 57.800404 | D7: =INDEX(PX_PHOENIXLTD,1) -> 398.27859 | E7: =INDEX(PX_NSEI,1) -> 16496.449 | F7: ='5Y_Price_Returns'!F6 -> 369.70001
A8: Final price P_final | B8: =INDEX(PX_OBEROIRLTY,COUNT(PX_OBEROIRLTY)) -> 1872.9 | C8: =INDEX(PX_ANANTRAJ,COUNT(PX_ANANTRAJ)) -> 605.25 | D8: =INDEX(PX_PHOENIXLTD,COUNT(PX_PHOENIXLTD)) -> 1901.7 | E8: =INDEX(PX_NSEI,COUNT(PX_NSEI)) -> 24090.85 | F8: ='5Y_Price_Returns'!F1216 -> 918.70001
A9: Total return | B9: =B8/B7-1 -> 1.8875355 | C9: =C8/C7-1 -> 9.4713802 | D9: =D8/D7-1 -> 3.7747983 | E9: =E8/E7-1 -> 0.46036576 | F9: =F8/F7-1 -> 1.4849878
A10: CAGR (P_f/P_i)^(1/5)-1 | B10: =(B8/B7)^(1/B23)-1 -> 0.23571047 | C10: =(C8/C7)^(1/C23)-1 -> 0.59802199 | D10: =(D8/D7)^(1/D23)-1 -> 0.36619517 | E10: =(E8/E7)^(1/E23)-1 -> 0.078511862 | F10: =(F8/F7)^(1/F23)-1 -> 0.20423464
A11: Daily st.dev of log returns | B11: =STDEV(LR_OBEROIRLTY) -> 0.021525127 | C11: =STDEV(LR_ANANTRAJ) -> 0.031672186 | D11: =STDEV(LR_PHOENIXLTD) -> 0.022445259 | E11: =STDEV(LR_NSEI) -> 0.0087131731 | F11: =STDEV(LR_CNXREALTY) -> 0.017778733
A12: Annualised volatility σ×√252 | B12: =B11*SQRT(TDays) -> 0.3417008 | C12: =C11*SQRT(TDays) -> 0.50278037 | D12: =D11*SQRT(TDays) -> 0.35630744 | E12: =E11*SQRT(TDays) -> 0.13831734 | F12: =F11*SQRT(TDays) -> 0.28222864
A13: Sharpe ratio (CAGR-Rf)/σ | B13: =(B10-Rf)/B12 -> 0.49081087 | C13: =(C10-Rf)/C12 -> 1.0541819 | D13: =(D10-Rf)/D12 -> 0.83690414 | E13: =(E10-Rf)/E12 -> 0.075998154 | F13: =(F10-Rf)/F12 -> 0.48271019
A14: Beta vs Nifty Realty | B14: =COVAR(BR_OBEROIRLTY,BR_CNXREALTY)/VARP(BR_CNXREALTY) -> 0.95161831 | C14: =COVAR(BR_ANANTRAJ,BR_CNXREALTY)/VARP(BR_CNXREALTY) -> 0.91844177 | D14: =COVAR(BR_PHOENIXLTD,BR_CNXREALTY)/VARP(BR_CNXREALTY) -> 0.70896333 | E14: =COVAR(BR_NSEI,BR_CNXREALTY)/VARP(BR_CNXREALTY) -> 0.34646837 | F14: =COVAR(BR_CNXREALTY,BR_CNXREALTY)/VARP(BR_CNXREALTY) -> 1
A15: Beta vs Nifty 50 | B15: =COVAR(LR_OBEROIRLTY,LR_NSEI)/VARP(LR_NSEI) -> 1.3279108 | C15: =COVAR(LR_ANANTRAJ,LR_NSEI)/VARP(LR_NSEI) -> 1.6667218 | D15: =COVAR(LR_PHOENIXLTD,LR_NSEI)/VARP(LR_NSEI) -> 0.91355753 | E15: =COVAR(LR_NSEI,LR_NSEI)/VARP(LR_NSEI) -> 1 | F15: =COVAR(BR_CNXREALTY,BR_NSEI)/VARP(BR_NSEI) -> 1.4171737
A16: Correlation vs Nifty Realty | B16: =CORREL(BR_OBEROIRLTY,BR_CNXREALTY) -> 0.78063032 | C16: =CORREL(BR_ANANTRAJ,BR_CNXREALTY) -> 0.51250402 | D16: =CORREL(BR_PHOENIXLTD,BR_CNXREALTY) -> 0.55978153 | E16: =CORREL(BR_NSEI,BR_CNXREALTY) -> 0.70071811 | F16: =CORREL(BR_CNXREALTY,BR_CNXREALTY) -> 1
A17: Maximum drawdown | B17: -0.3886199 | C17: -0.56582934 | D17: -0.31631136 | E17: -0.17229756 | F17: -0.43393028
A18: Downside deviation (ann.) | B18: 0.22884846 | C18: 0.35325144 | D18: 0.22247378 | E18: 0.10175896 | F18: 0.2011414
A19: Sortino ratio | B19: =(B10-Rf)/B18 -> 0.73284506 | C19: =(C10-Rf)/C18 -> 1.50041 | D19: =(D10-Rf)/D18 -> 1.3403609 | E19: =(E10-Rf)/E18 -> 0.10330159 | F19: =(F10-Rf)/F18 -> 0.67730781
A20: Best / worst daily log return | B20: =MAX(LR_OBEROIRLTY) -> 0.12104872 | C20: =MAX(LR_ANANTRAJ) -> 0.15578359 | D20: =MAX(LR_PHOENIXLTD) -> 0.075549525 | E20: =MAX(LR_NSEI) -> 0.03747214 | F20: =MAX(LR_CNXREALTY) -> 0.083025163
A21: Worst daily log return | B21: =MIN(LR_OBEROIRLTY) -> -0.10342401 | C21: =MIN(LR_ANANTRAJ) -> -0.22310599 | D21: =MIN(LR_PHOENIXLTD) -> -0.082067687 | E21: =MIN(LR_NSEI) -> -0.061124196 | F21: =MIN(LR_CNXREALTY) -> -0.10119765
A22: Observations (daily) | B22: =COUNT(LR_OBEROIRLTY) -> 1239 | C22: =COUNT(LR_ANANTRAJ) -> 1239 | D22: =COUNT(LR_PHOENIXLTD) -> 1239 | E22: =COUNT(LR_NSEI) -> 1239 | F22: =COUNT(LR_CNXREALTY) -> 1198
A23: Years spanned by series | B23: 5.0102669 | C23: 5.0102669 | D23: 5.0102669 | E23: 5.0102669 | F23: 4.8980151
A25: Beta note | B25: Nifty Realty betas use the gap-free overlapping window (first 1205 sessions, to 2026-07-17); the index series ends earlier than the stock series on the vendor feed. Beta = COVAR/VARP (population covariance over population variance) which is algebraically identical to the sample-based COVARIANCE.S/VAR.S ratio.

Sheet Correlation_Covariance
A1: CORRELATION & ANNUALISED VARIANCE-COVARIANCE MATRIX
A3: 3x3 matrices for the selected portfolio, computed live from daily log returns.
A5: CORRELATION MATRIX ρ(i,j)
B6: Oberoi Realty | C6: Anant Raj Ltd | D6: Phoenix Mills
A7: Oberoi Realty | B7: =CORREL(LR_OBEROIRLTY,LR_OBEROIRLTY) -> 1 | C7: =CORREL(LR_OBEROIRLTY,LR_ANANTRAJ) -> 0.40432863 | D7: =CORREL(LR_OBEROIRLTY,LR_PHOENIXLTD) -> 0.32030711
A8: Anant Raj Ltd | B8: =CORREL(LR_ANANTRAJ,LR_OBEROIRLTY) -> 0.40432863 | C8: =CORREL(LR_ANANTRAJ,LR_ANANTRAJ) -> 1 | D8: =CORREL(LR_ANANTRAJ,LR_PHOENIXLTD) -> 0.24562691
A9: Phoenix Mills | B9: =CORREL(LR_PHOENIXLTD,LR_OBEROIRLTY) -> 0.32030711 | C9: =CORREL(LR_PHOENIXLTD,LR_ANANTRAJ) -> 0.24562691 | D9: =CORREL(LR_PHOENIXLTD,LR_PHOENIXLTD) -> 1
A12: ANNUALISED VARIANCE-COVARIANCE MATRIX Σ = cov(i,j) × 252
B13: Oberoi Realty | C13: Anant Raj Ltd | D13: Phoenix Mills
A14: Oberoi Realty | B14: =COVAR(LR_OBEROIRLTY,LR_OBEROIRLTY)*COUNT(LR_OBEROIRLTY)/(COUNT(LR_OBEROIRLTY)-1)*TDays -> 0.11675943 | C14: =COVAR(LR_OBEROIRLTY,LR_ANANTRAJ)*COUNT(LR_OBEROIRLTY)/(COUNT(LR_OBEROIRLTY)-1)*TDays -> 0.069463841 | D14: =COVAR(LR_OBEROIRLTY,LR_PHOENIXLTD)*COUNT(LR_OBEROIRLTY)/(COUNT(LR_OBEROIRLTY)-1)*TDays -> 0.038997563
A15: Anant Raj Ltd | B15: =COVAR(LR_ANANTRAJ,LR_OBEROIRLTY)*COUNT(LR_ANANTRAJ)/(COUNT(LR_ANANTRAJ)-1)*TDays -> 0.069463841 | C15: =COVAR(LR_ANANTRAJ,LR_ANANTRAJ)*COUNT(LR_ANANTRAJ)/(COUNT(LR_ANANTRAJ)-1)*TDays -> 0.2527881 | D15: =COVAR(LR_ANANTRAJ,LR_PHOENIXLTD)*COUNT(LR_ANANTRAJ)/(COUNT(LR_ANANTRAJ)-1)*TDays -> 0.044002682
A16: Phoenix Mills | B16: =COVAR(LR_PHOENIXLTD,LR_OBEROIRLTY)*COUNT(LR_PHOENIXLTD)/(COUNT(LR_PHOENIXLTD)-1)*TDays -> 0.038997563 | C16: =COVAR(LR_PHOENIXLTD,LR_ANANTRAJ)*COUNT(LR_PHOENIXLTD)/(COUNT(LR_PHOENIXLTD)-1)*TDays -> 0.044002682 | D16: =COVAR(LR_PHOENIXLTD,LR_PHOENIXLTD)*COUNT(LR_PHOENIXLTD)/(COUNT(LR_PHOENIXLTD)-1)*TDays -> 0.12695499
A19: Annualised σ (√diagonal) | B19: =SQRT(B14) -> 0.3417008 | C19: =SQRT(C15) -> 0.50278037 | D19: =SQRT(D16) -> 0.35630744
A20: Cross-check vs Risk_Return_Metrics | B20: =B19-Risk_Return_Metrics!B12 -> 0 | C20: =C19-Risk_Return_Metrics!C12 -> 0 | D20: =D19-Risk_Return_Metrics!D12 -> 0
A22: Note | B22: COVAR returns the population covariance; multiplying by n/(n-1) converts it to the sample covariance (equivalent to COVARIANCE.S) before annualising by 252. Row 20 must read ~0.000000, confirming the covariance diagonal reconciles to the independently computed volatilities.

Sheet Portfolio_Optimization
A1: MARKOWITZ PORTFOLIO OPTIMISATION — CLIENT A vs CLIENT B
A3: Yellow cells are live inputs: change a weight and every metric below recalculates. | E3: Shrinkage k → | F3: 0.4
A5: EXPECTED RETURN INPUTS
A6: Asset | B6: Oberoi Realty | C6: Anant Raj Ltd | D6: Phoenix Mills
A7: 5Y realised CAGR (historical) | B7: =Risk_Return_Metrics!B10 -> 0.23571047 | C7: =Risk_Return_Metrics!C10 -> 0.59802199 | D7: =Risk_Return_Metrics!D10 -> 0.36619517
A8: Shrunk expected return μ (used) | B8: =AVERAGE($B$7:$D$7)+(1-$F$3)*(B7-AVERAGE($B$7:$D$7)) -> 0.30141663 | C8: =AVERAGE($B$7:$D$7)+(1-$F$3)*(C7-AVERAGE($B$7:$D$7)) -> 0.51880354 | D8: =AVERAGE($B$7:$D$7)+(1-$F$3)*(D7-AVERAGE($B$7:$D$7)) -> 0.37970745
A9: Annualised volatility σ | B9: =Risk_Return_Metrics!B12 -> 0.3417008 | C9: =Risk_Return_Metrics!C12 -> 0.50278037 | D9: =Risk_Return_Metrics!D12 -> 0.35630744
A10: Beta vs Nifty Realty | B10: =Risk_Return_Metrics!B14 -> 0.95161831 | C10: =Risk_Return_Metrics!C14 -> 0.91844177 | D10: =Risk_Return_Metrics!D14 -> 0.70896333
A12: CLIENT A · RISK-AVERSE · MINIMUM-VARIANCE MANDATE
A13: Asset | B13: Oberoi Realty | C13: Anant Raj Ltd | D13: Phoenix Mills | E13: Σ w
A14: Weight w(i) ← EDITABLE | B14: 0.45 | C14: 0.109393 | D14: 0.440607 | E14: =SUM(B14:D14) -> 1
A15: Constraint set | B15: Objective: minimise portfolio variance subject to Σw = 100%, 10% ≤ w ≤ 45%. Min-variance weights are independent of the expected-return vector, so this allocation is immune to estimation error in μ — the key reason it suits a capital-preservation mandate.
A16: Bounds check (all within limits) | B16: =IF(AND(MIN(B14:D14)>=0.1,MAX(B14:D14)<=0.45,ABS(E14-1)<0.0001),"PASS","REVIEW") -> PASS | C16: bounds [10%, 45%], Σw = 100%
A19: CLIENT B · RISK-SEEKER · GROWTH-WEIGHTED MAX-SHARPE
A20: Asset | B20: Oberoi Realty | C20: Anant Raj Ltd | D20: Phoenix Mills | E20: Σ w
A21: Weight w(i) ← EDITABLE | B21: 0.125941 | C21: 0.4 | D21: 0.474059 | E21: =SUM(B21:D21) -> 1
A22: Constraint set | B22: Objective: maximise (μp − Rf)/σp subject to Σw = 100%, 5% ≤ w ≤ 60%, and a hard floor of 40% in the highest-growth asset (Anant Raj Ltd).
A23: Bounds check (all within limits) | B23: =IF(AND(MIN(B21:D21)>=0.05,MAX(B21:D21)<=0.6,ABS(E21-1)<0.0001),"PASS","REVIEW") -> PASS | C23: bounds [5%, 60%], Σw = 100%
A26: PORTFOLIO MATHEMATICS — Client A (Risk-Averse)
A27: Expected return μp = Σ wi·μi | B27: =SUMPRODUCT(B14:D14,MU) -> 0.35969272
A28: Portfolio variance σp² (explicit expansion) | B28: =B14^2*Correlation_Covariance!$B$14+C14^2*Correlation_Covariance!$C$15+D14^2*Correlation_Covariance!$D$16+2*B14*C14*Correlation_Covariance!$C$14+2*B14*D14*Correlation_Covariance!$D$14+2*C14*D14*Correlation_Covariance!$D$15 -> 0.077860315
A29: Portfolio variance σp² = wᵀΣw (MMULT) | B29: =SUMPRODUCT(MMULT(B14:D14,COVMAT),B14:D14) -> 0.077860315
A30: Reconciliation (must be 0) | B30: =B28-B29 -> 0
A31: Portfolio volatility σp = √(wᵀΣw) | B31: =SQRT(B28) -> 0.27903461
A32: Sharpe ratio (μp − Rf)/σp | B32: =(B27-Rf)/B31 -> 1.0453639
A33: Portfolio beta vs Nifty Realty | B33: =SUMPRODUCT(B14:D14,$B$10:$D$10) -> 0.84107355
A34: Weighted-average σ (undiversified) | B34: =SUMPRODUCT(B14:D14,$B$9:$D$9) -> 0.36575756 | C34: vs σp — the gap is the diversification benefit
A35: Diversification ratio | B35: =B34/B31 -> 1.3107964
A36: Historical max drawdown (daily-rebalanced) | B36: -0.30574177
A37: Daily VaR 95% (historical) | B37: -0.027204763
A38: Sortino ratio | B38: 1.5414701
A40: PORTFOLIO MATHEMATICS — Client B (Risk-Seeker)
A41: Expected return μp = Σ wi·μi | B41: =SUMPRODUCT(B21:D21,MU) -> 0.42548586
A42: Portfolio variance σp² (explicit expansion) | B42: =B21^2*Correlation_Covariance!$B$14+C21^2*Correlation_Covariance!$C$15+D21^2*Correlation_Covariance!$D$16+2*B21*C21*Correlation_Covariance!$C$14+2*B21*D21*Correlation_Covariance!$D$14+2*C21*D21*Correlation_Covariance!$D$15 -> 0.099172024
A43: Portfolio variance σp² = wᵀΣw (MMULT) | B43: =SUMPRODUCT(MMULT(B21:D21,COVMAT),B21:D21) -> 0.099172024
A44: Reconciliation (must be 0) | B44: =B42-B43 -> 0
A45: Portfolio volatility σp = √(wᵀΣw) | B45: =SQRT(B42) -> 0.3149159
A46: Sharpe ratio (μp − Rf)/σp | B46: =(B41-Rf)/B45 -> 1.1351788
A47: Portfolio beta vs Nifty Realty | B47: =SUMPRODUCT(B21:D21,$B$10:$D$10) -> 0.82331492
A48: Weighted-average σ (undiversified) | B48: =SUMPRODUCT(B21:D21,$B$9:$D$9) -> 0.41305704 | C48: vs σp — the gap is the diversification benefit
...

Sheet Screener_Fundamentals
A1: SCREENER.IN FUNDAMENTALS — PEER UNIVERSE (10 DEVELOPERS)
A3: Consolidated financials, trailing 5 fiscal years. Source: screener.in company pages.
A5: Company | B5: Ticker | C5: Market Cap (Cr) | D5: Current Price | E5: Stock P/E | F5: P/B | G5: Dividend Yield % | H5: Sales CAGR 5Y % | I5: Sales CAGR 3Y % | J5: Profit CAGR 5Y % | K5: ROCE % (latest) | L5: ROCE 5Y avg % | M5: OPM % latest | N5: D/E FY20 | O5: D/E latest | P5: D/E 5Y avg | Q5: CFO/EBITDA % | R5: Interest Coverage (5Y EBITDA/Int) | S5: CFO 5Y total (Cr) | T5: Borrowings latest (Cr)
A6: DLF Ltd | B6: DLF.NS | C6: 168272 | D6: 680 | E6: 39.1 | F6: 3.6956522 | G6: 1.18 | H6: 9 | I6: 13 | J6: 29 | K6: 6.32 | L6: 5.8 | M6: 18 | N6: 0.11501018 | O6: 0.0067292679 | P6: 0.085845318 | Q6: 211.21189 | R6: 4.6475368 | S6: 19328 | T6: 306
A7: Macrotech Developers | B7: LODHA.NS | C7: 127301 | D7: 1274 | E7: 30.9 | F7: 5.4678112 | G7: 0.33 | H7: 25 | I7: 21 | J7: 58 | K7: 16.4 | L7: 12.2 | M7: 30 | N7: 0.95299851 | O7: 0.42497638 | P7: 0.5771365 | Q7: 61.82473 | R7: 5.5281174 | S7: 9785 | T7: 9896
A8: Phoenix Mills | B8: PHOENIXLTD.NS | C8: 68564 | D8: 1917 | E8: 52.9 | F8: 6.2442997 | G8: 0.13 | H8: 34 | I8: 19 | J8: 83 | K8: 12.8 | L8: 10.2 | M8: 60 | N8: 0.60489139 | O8: 0.48439348 | P8: 0.50731254 | Q8: 95.376286 | R8: 5.0686059 | S8: 8808 | T8: 5323
A9: Prestige Estates | B9: PRESTIGE.NS | C9: 68400 | D9: 1588 | E9: 60.1 | F9: 4.2010582 | G9: 0.13 | H9: 12 | I9: 15 | J9: 21 | K9: 10.4 | L9: 9.4 | M9: 29 | N9: 0.81495327 | O9: 1.0851718 | P9: 0.97823754 | Q9: 67.665692 | R9: 2.2397671 | S9: 8331 | T9: 17659
A10: Oberoi Realty | B10: OBEROIRLTY.NS | C10: 67994 | D10: 1870 | E10: 25.7 | F10: 3.7931034 | G10: 0.43 | H10: 24 | I10: 13 | J10: 27 | K10: 17.3 | L10: 15.6 | M10: 56 | N10: 0.27407123 | O10: 0.1576275 | P10: 0.22900396 | Q10: 41.399967 | R10: 12.447395 | S10: 5045 | T10: 2825
A11: Godrej Properties | B11: GODREJPROP.NS | C11: 61122 | D11: 2029 | E11: 37.8 | F11: 3.1902516 | G11: 0.49 | H11: 46 | I11: 32 | J11: 56 | K11: 7.63 | L11: 6.4 | M11: -9 | N11: 0.59896254 | O11: 0.82971393 | P11: 0.7843538 | Q11: 1630.6324 | R11: -0.62935323 | S11: -8251 | T11: 15894
A12: Anant Raj Ltd | B12: ANANTRAJ.NS | C12: 21814 | D12: 606 | E12: 37.7 | F12: 3.7639752 | G12: 0.16 | H12: 59 | I12: 38 | J12: 120 | K12: 12.1 | L12: 8 | M12: 26 | N12: 0.486169 | O12: 0.1176369 | P12: 0.25461785 | Q12: 14.131054 | R12: 15 | S12: 248 | T12: 681
A13: Brigade Enterprises | B13: BRIGADE.NS | C13: 20954 | D13: 642 | E13: 30.8 | F13: 3.0717703 | G13: 0.31 | H13: 24 | I13: 18 | J13: 89 | K13: 10.5 | L13: 10.2 | M13: 25 | N13: 1.6859107 | O13: 0.9300689 | P13: 1.3024403 | Q13: 56.04357 | R13: 2.5041795 | S13: 3190 | T13: 6344
A14: Sobha Ltd | B14: SOBHA.NS | C14: 13583 | D14: 1270 | E14: 58.9 | F14: 2.8798186 | G14: 0.47 | H14: 20 | I14: 16 | J14: 25 | K14: 6.86 | L14: 7.6 | M14: 6 | N14: 1.0437474 | O14: 0.22394068 | P14: 0.6222329 | Q14: 182.34305 | R14: 1.5704225 | S14: 3253 | T14: 1057
A15: Mahindra Lifespace | B15: MAHLIFE.NS | C15: 7843 | D15: 368 | E15: 25.2 | F15: 2.1647059 | G15: 0.95 | H15: 48 | I15: 25 | J15: 42 | K15: 7.64 | L15: 3 | M15: -10 | N15: 0.15986585 | O15: 0.18251999 | P15: 0.34359582 | Q15: 295.15152 | R15: -12 | S15: -1948 | T15: 662
A17: Reading the shading | B17: Green→red scales on D/E (lower is better); red→green on CFO/EBITDA (higher is better). Interest coverage below 2.0x is flagged red. Highlighted rows are the three selected holdings.
A18: Negative-EBITDA caveat | B18: Godrej Properties and Mahindra Lifespace report negative consolidated operating profit in several years because their asset-light development-management/JV model routes economics through other income and share of associates. EBITDA-based interest coverage and CFO/EBITDA are therefore not meaningful for those two names and were winsorised before scoring rather than taken at face value.
A21: MULTI-FACTOR ARCHETYPE SCORES (z-scored across the universe)
A22: Company | B22: Fortress score | C22: Growth score | D22: Annuity score | E22: Composite
A23: Anant Raj Ltd | B23: 0.32496928 | C23: 1.7340573 | D23: 0.016102758 | E23: 0.69170978
A24: Oberoi Realty | B24: 1.2373601 | C24: -0.29746514 | D24: 0.6257041 | E24: 0.52186634
A25: Phoenix Mills | B25: 0.44224889 | C25: 0.27390829 | D25: 0.51428739 | E25: 0.41014819
A26: Macrotech Developers | B26: -0.02829571 | C26: 0.15031675 | D26: 0.054190495 | E26: 0.058737177
A27: DLF Ltd | B27: 0.62957983 | C27: -0.79927672 | D27: 0.028421129 | E27: -0.047091921
A28: Godrej Properties | B28: -0.77497032 | C28: 0.27981739 | D28: -0.07575488 | E28: -0.1903026
A29: Brigade Enterprises | B29: -0.70356149 | C29: -0.067380593 | D29: -0.11137703 | E29: -0.29410637
A30: Mahindra Lifespace | B30: -0.18435134 | C30: -0.23101374 | D30: -0.6465198 | E30: -0.35396163
A31: Prestige Estates | B31: -0.71451549 | C31: -0.41068797 | D31: 0.0066079414 | E31: -0.37286517
A32: Sobha Ltd | B32: -0.22846372 | C32: -0.63227556 | D32: -0.4116621 | E32: -0.42413379

Sheet Assumptions_Notes
A1: ASSUMPTIONS, METHODOLOGY & DATA LINEAGE
A3: Full reproducibility record for the model.
A5: Price source | B5: Yahoo Finance daily adjusted closes via yfinance (auto_adjust=True: split- and dividend-adjusted). NSE tickers with .NS suffix. Window 2021-08-23 → 2026-08-27, 1240 sessions.
A6: Fundamental source | B6: screener.in consolidated company pages (P&L, balance sheet, cash flow, ratios, compounded-growth tables), parsed with BeautifulSoup. Raw HTML retained in ./data/raw_<SLUG>.html for audit.
A7: Pre-sales & land bank | B7: screener.in exposes these in its 'Insights' block only to logged-in subscribers; the values render as masked placeholders for anonymous requests and were therefore NOT scraped. Pre-sales momentum and land-bank depth are treated qualitatively in the PDF report and are not inputs to the quantitative score.
A8: Risk-free rate | B8: 6.80%, the mandated RBI 10Y G-Sec / 91-day T-bill baseline. Held constant across all Sharpe/Sortino calculations.
A9: Return convention | B9: Daily returns are logarithmic, ln(Pt/Pt-1), for additivity and volatility estimation. Monthly returns are simple month-end changes. CAGR uses simple price relatives over the actual year-fraction of the window.
A10: Annualisation | B10: 252 trading days. σ_annual = σ_daily × √252; covariance matrix scaled by 252.
A11: Beta window | B11: Nifty Realty (^CNXREALTY) terminates 2026-07-17 on the vendor feed, 35 sessions before the stock series. Realty betas use the gap-free overlapping window of 1205 sessions; Nifty 50 betas use the full 1239 return observations.
A12: Excel function dialect | B12: Classic functions only (STDEV, VAR, VARP, COVAR, CORREL, SUMPRODUCT, MMULT, TRANSPOSE, INDEX, COUNT). STDEV is identical to STDEV.S; VAR is identical to VAR.S. COVAR returns population covariance, so the covariance matrix multiplies by n/(n-1) to match COVARIANCE.S. Beta uses COVAR/VARP, algebraically identical to COVARIANCE.S/VAR.S. This avoids _xlfn compatibility errors across Excel, LibreOffice and Sheets.
A13: Expected returns | B13: Realised 5Y CAGR shrunk 40% toward the cross-sectional mean (James-Stein style) to control estimation error before optimisation. Both the raw and shrunk vectors are shown on Portfolio_Optimization.
A14: Client A objective | B14: Minimise wᵀΣw subject to Σw=1, 0.10 ≤ w ≤ 0.45. Solved with SLSQP from four starting points.
A15: Client B objective | B15: Maximise (wᵀμ − Rf)/√(wᵀΣw) subject to Σw=1, 0.05 ≤ w ≤ 0.60, w[ANANTRAJ.NS] ≥ 40%.
A16: Drawdown / VaR | B16: Computed on the daily-rebalanced portfolio log-return series over the full window; VaR 95% is the historical 5th percentile of daily returns, not a parametric estimate.
... A18: Not investment advice | B18: Prepared as a quantitative research exercise. No representation is made that these allocations are suitable for any specific investor.
