Workbook

Sheet Cover
B2: INFOSYS LIMITED
B3: Financial Statement & Valuation Analysis
B4: Comparative & Common-Size Analysis | Ratio Analysis | Predictability Scores | DCF & Comparable-Company Valuation
B6: Company | C6: Infosys Limited (NSE/BSE: INFY) - Consolidated financial statements
B8: Financial years covered | C8: FY2023-24, FY2024-25, FY2025-26 (year ended March 31); DCF forecast FY2026-27E to FY2030-31E
B10: Source documents | C10: Infosys Integrated Annual Report 2024-25; Infosys Integrated Annual Report 2025-26; Infosys IR three-year overview (IFRS); TCS/HCL Tech/Wipro/Tech Mahindra annual reports & screener.in
B12: Market data as of | C12: 6-12 August 2026 (NSE) — see individual sheets for exact dates/sources
B14: Currency / units | C14: All figures in ₹ Crore (1 crore = 10 million) unless stated otherwise
B19: Contents
B21: Comparative & Common-Size Analysis, Trend Analysis
B22: • | C22: Data-BS / Data-PL / Data-CF — 3-year consolidated source figures (Balance Sheet, P&L, Cash Flow)
B23: • | C23: Comparative BS — FY24-25-26, ₹ and % change, with observations
B24: • | C24: Comparative PL — FY24-25-26, ₹ and % change, with observations
B25: • | C25: Common-Size BS — % of Total Assets, with observations
B26: • | C26: Common-Size PL — % of Revenue, with observations
B27: • | C27: Trend Analysis — Index, FY24 = 100, with observations
B29: Ratio Analysis
B30: • | C30: Ratio - Cover & Notes — methodology, sources & conventions for the ratio module
B31: • | C31: Input Data — Infosys FY25/FY26 input figures (IFRS three-year overview basis)
B32: • | C32: Ratio Analysis — all 19 ratios: Liquidity, Profitability, Efficiency, Solvency, Market — formula + calculation + interpretation
B33: • | C33: Peer Input Data — TCS & HCL Tech input figures
B34: • | C34: Peer Comparison — Infosys vs TCS vs HCL Tech, ratio-by-ratio benchmarking
B36: Predictability Scores
B37: • | C37: Predictability Scores — Altman Z-Score (3-yr trend) and Beneish M-Score (FY25→FY26), with interpretation
B39: Valuation - Method 1: DCF
B40: • | C40: DCF - Cover & Notes — model map & headline outputs
B41: • | C41: All-in-One DCF — entire model on one sheet (assumptions through valuation)
B42: • | C42: Assumptions — revenue/margin/working-capital drivers, WACC build-up, terminal growth, share data
B43: • | C43: Income Statement — FY24A-FY26A actuals & FY27E-FY31E forecast
B44: • | C44: Balance Sheet — fully linked, FY24A-FY31E
B45: • | C45: Cash Flow — statement of cash flows & FCF build
B46: • | C46: WC & PPE Schedule — working capital and fixed-asset roll-forward
B47: • | C47: Capital Structure — debt, cash & WACC support schedule
B48: • | C48: DCF Valuation — FCFF build, EV-to-equity bridge, intrinsic value & sensitivity table
B49: • | C49: Charts & Outputs — output dashboard and charts
B51: Valuation - Method 2: Comparable Companies
B52: • | C52: Comps - EV Multiples — EV/EBITDA, EV/EBIT, EV/Revenue, P/E for 4 peers (TCS, HCL Tech, Wipro, Tech Mahindra); mean/median/min/max and implied valuation of Infosys
B55: Note on conventions: Blue text = hardcoded source figures / inputs (cited). Black text = formulas. Green text = links pulling from another sheet. Yellow fill = key assumptions you can flex. The Ratio Analysis, Peer Comparison and full DCF modules were built and supplied directly; this workbook integrates them alongside the comparative/common-size/trend/predictability-score analysis and the EV-multiples comparable-company valuation into a single consolidated file. All formulas recalculate automatically if source or assumption cells are changed.

Sheet Data-BS
A1: Infosys Limited — Consolidated Balance Sheet (Source Data, ₹ Crore)
B3: Particulars | D3: FY2024 | E3: FY2025 | F3: FY2026
B4: ASSETS
B5: Non-current assets
B6: Property, plant and equipment | D6: 12370 | E6: 11778 | F6: 12651
B7: Right-of-use assets | D7: 6552 | E7: 6311 | F7: 6177
B8: Capital work-in-progress | D8: 293 | E8: 814 | F8: 526
B9: Goodwill | D9: 7303 | E9: 10106 | F9: 12117
B10: Other intangible assets | D10: 1397 | E10: 2766 | F10: 2825
B11: Non-current investments | D11: 11708 | E11: 11059 | F11: 8930
B12: Loans (non-current) | D12: 34 | E12: 16 | F12: 6
B13: Other financial assets (non-current) | D13: 3105 | E13: 3511 | F13: 2776
B14: Deferred tax assets (net) | D14: 454 | E14: 1108 | F14: 2264
B15: Income tax assets (net) - non-current | D15: 3045 | E15: 1622 | F15: 666
B16: Other non-current assets | D16: 2121 | E16: 2713 | F16: 3540
B17: Total non-current assets | D17: =SUM(D6:D16) -> 48382 | E17: =SUM(E6:E16) -> 51804 | F17: =SUM(F6:F16) -> 52478
B18: Current assets
B19: Current investments | D19: 12915 | E19: 12482 | F19: 12950
B20: Trade receivables | D20: 30193 | E20: 31158 | F20: 35234
B21: Cash and cash equivalents | D21: 14786 | E21: 24455 | F21: 22201
B22: Loans (current) | D22: 248 | E22: 249 | F22: 234
B23: Other financial assets (current) | D23: 12085 | E23: 13840 | F23: 15890
B24: Income tax assets (net) - current | D24: 6397 | E24: 2975 | F24: 1835
B25: Other current assets | D25: 12808 | E25: 11940 | F25: 15145
B26: Total current assets | D26: =SUM(D19:D25) -> 89432 | E26: =SUM(E19:E25) -> 97099 | F26: =SUM(F19:F25) -> 103489
B27: TOTAL ASSETS | D27: =D17+D26 -> 137814 | E27: =E17+E26 -> 148903 | F27: =F17+F26 -> 155967
B28: EQUITY AND LIABILITIES
B29: Equity
B30: Equity share capital | D30: 2071 | E30: 2073 | F30: 2024
B31: Other equity | D31: 86045 | E31: 93745 | F31: 90828
B32: Total equity attributable to owners | D32: =D30+D31 -> 88116 | E32: =E30+E31 -> 95818 | F32: =F30+F31 -> 92852
B33: Non-controlling interests | D33: 345 | E33: 385 | F33: 445
B34: Total equity | D34: =D32+D33 -> 88461 | E34: =E32+E33 -> 96203 | F34: =F32+F33 -> 93297
B35: Non-current liabilities
B36: Lease liabilities (non-current) | D36: 6400 | E36: 5772 | F36: 6016
B37: Other financial liabilities (non-current) | D37: 2130 | E37: 2141 | F37: 2092
B38: Deferred tax liabilities (net) | D38: 1794 | E38: 1722 | F38: 1679
B39: Other non-current liabilities | D39: 235 | E39: 215 | F39: 561
B40: Total non-current liabilities | D40: =SUM(D36:D39) -> 10559 | E40: =SUM(E36:E39) -> 9850 | F40: =SUM(F36:F39) -> 10348
B41: Current liabilities
...

Sheet Data-PL
A1: Infosys Limited — Consolidated Statement of Profit & Loss (Source Data, ₹ Crore)
B3: Particulars | D3: FY2024 | E3: FY2025 | F3: FY2026
B4: Revenue from operations | D4: 153670 | E4: 162990 | F4: 178650
B5: Other income, net | D5: 4711 | E5: 3600 | F5: 4322
B6: Total income | D6: =D4+D5 -> 158381 | E6: =E4+E5 -> 166590 | F6: =F4+F5 -> 182972
B7: EXPENSES
B8: Employee benefit expenses | D8: 82620 | E8: 85950 | F8: 95094
B9: Cost of technical sub-contractors | D9: 12232 | E9: 12937 | F9: 15421
B10: Travel expenses | D10: 1759 | E10: 1894 | F10: 2097
B11: Cost of software packages and others | D11: 13515 | E11: 15911 | F11: 15722
B12: Communication expenses | D12: 677 | E12: 620 | F12: 603
B13: Consultancy and professional charges | D13: 1726 | E13: 1655 | F13: 2090
B14: Depreciation and amortization expenses | D14: 4678 | E14: 4812 | F14: 4902
B15: Finance cost | D15: 470 | E15: 416 | F15: 416
B16: Other expenses | D16: 4716 | E16: 4787 | F16: 5343
B17: Total expenses | D17: =SUM(D8:D16) -> 122393 | E17: =SUM(E8:E16) -> 128982 | F17: =SUM(F8:F16) -> 141688
B18: Profit before exceptional item and tax | D18: =D6-D17 -> 35988 | E18: =E6-E17 -> 37608 | F18: =F6-F17 -> 41284
B19: Exceptional item (Impact of Labour Codes) | D19: 0 | E19: 0 | F19: 1289
B20: Profit before tax | D20: =D18-D19 -> 35988 | E20: =E18-E19 -> 37608 | F20: =F18-F19 -> 39995
B21: Current tax | D21: 8390 | E21: 12130 | F21: 11767
B22: Deferred tax | D22: 1350 | E22: -1272 | F22: -1246
B23: Total tax expense | D23: =D21+D22 -> 9740 | E23: =E21+E22 -> 10858 | F23: =F21+F22 -> 10521
B24: Profit for the year | D24: =D20-D23 -> 26248 | E24: =E20-E23 -> 26750 | F24: =F20-F23 -> 29474
B25: Profit attributable to owners of the Company | D25: 26233 | E25: 26713 | F25: 29440
B26: Profit attributable to non-controlling interests | D26: 15 | E26: 37 | F26: 34
B27: EPS — Basic (₹) | D27: 63.39 | E27: 64.5 | F27: 71.58
B28: EPS — Diluted (₹) | D28: 63.29 | E28: 64.34 | F28: 71.46
B29: Weighted avg equity shares — Basic (Cr) | D29: 413.86 | E29: 414.16 | F29: 411.28
B30: Weighted avg equity shares — Diluted (Cr) | D30: 414.47 | E30: 415.21 | F30: 412.01
B32: Source: Infosys Integrated Annual Report 2024-25 & 2025-26, Consolidated Statement of Profit and Loss, as furnished by user.

Sheet Data-CF
A1: Infosys Limited — Consolidated Statement of Cash Flows (Source Data, ₹ Crore)
B3: Particulars | C3: FY2024 | D3: FY2025 | E3: FY2026
B4: Net cash generated by operating activities (CFO) | C4: 25210 | D4: 35694 | E4: 33986
B5: Net cash from / (used in) investing activities (CFI) | C5: -5009 | D5: -1946 | E5: 1946
B6: Net cash used in financing activities (CFF) | C6: -17504 | D6: -24161 | E6: -39786
B7: Net increase / (decrease) in cash and cash equivalents | C7: =C4+C5+C6 -> 2697 | D7: =D4+D5+D6 -> 9587 | E7: =E4+E5+E6 -> -3854
B8: Cash and cash equivalents — opening | C8: 12173 | D8: 14786 | E8: 24455
B9: Effect of exchange rate changes | C9: -84 | D9: 82 | E9: 1600
B10: Cash and cash equivalents — closing | C10: 14786 | D10: 24455 | E10: 22201
B12: Memo: Capital expenditure (PPE & intangibles) | C12: 2201 | D12: 2237 | E12: 2727
B13: Memo: Dividends paid (cash flow statement) | C13: 14692 | D13: 20287 | E13: 18653
B14: Memo: Buyback of equity shares | C14: 0 | D14: 0 | E14: 18058
B15: Memo: Depreciation & amortization (non-cash add-back) | C15: 4678 | D15: 4812 | E15: 4902
B18: Source: Infosys Integrated Annual Report 2024-25 & 2025-26, Consolidated Statement of Cash Flows, as furnished by user.

Sheet Comparative BS
A1: Comparative Balance Sheet — Infosys Limited (Consolidated)
B3: All ₹ in Crore. FY25 vs FY24 and FY26 vs FY25 shown side by side.
B4: Particulars | C4: FY2024 | D4: FY2025 | E4: FY2026 | F4: Change ₹ (FY25 vs FY24) | G4: Change % (FY25 vs FY24) | H4: Change ₹ (FY26 vs FY25) | I4: Change % (FY26 vs FY25)
B5: ASSETS
B6: Non-current assets
B7: Property, plant and equipment | C7: ='Data-BS'!D6 -> 12370 | D7: ='Data-BS'!E6 -> 11778 | E7: ='Data-BS'!F6 -> 12651 | F7: =D7-C7 -> -592 | G7: =IFERROR(F7/C7,"n.m.") -> -0.04785772 | H7: =E7-D7 -> 873 | I7: =IFERROR(H7/D7,"n.m.") -> 0.074121243
B8: Right-of-use assets | C8: ='Data-BS'!D7 -> 6552 | D8: ='Data-BS'!E7 -> 6311 | E8: ='Data-BS'!F7 -> 6177 | F8: =D8-C8 -> -241 | G8: =IFERROR(F8/C8,"n.m.") -> -0.036782662 | H8: =E8-D8 -> -134 | I8: =IFERROR(H8/D8,"n.m.") -> -0.021232768
B9: Capital work-in-progress | C9: ='Data-BS'!D8 -> 293 | D9: ='Data-BS'!E8 -> 814 | E9: ='Data-BS'!F8 -> 526 | F9: =D9-C9 -> 521 | G9: =IFERROR(F9/C9,"n.m.") -> 1.778157 | H9: =E9-D9 -> -288 | I9: =IFERROR(H9/D9,"n.m.") -> -0.35380835
B10: Goodwill | C10: ='Data-BS'!D9 -> 7303 | D10: ='Data-BS'!E9 -> 10106 | E10: ='Data-BS'!F9 -> 12117 | F10: =D10-C10 -> 2803 | G10: =IFERROR(F10/C10,"n.m.") -> 0.38381487 | H10: =E10-D10 -> 2011 | I10: =IFERROR(H10/D10,"n.m.") -> 0.1989907
B11: Other intangible assets | C11: ='Data-BS'!D10 -> 1397 | D11: ='Data-BS'!E10 -> 2766 | E11: ='Data-BS'!F10 -> 2825 | F11: =D11-C11 -> 1369 | G11: =IFERROR(F11/C11,"n.m.") -> 0.97995705 | H11: =E11-D11 -> 59 | I11: =IFERROR(H11/D11,"n.m.") -> 0.021330441
B12: Non-current investments | C12: ='Data-BS'!D11 -> 11708 | D12: ='Data-BS'!E11 -> 11059 | E12: ='Data-BS'!F11 -> 8930 | F12: =D12-C12 -> -649 | G12: =IFERROR(F12/C12,"n.m.") -> -0.055432183 | H12: =E12-D12 -> -2129 | I12: =IFERROR(H12/D12,"n.m.") -> -0.19251289
B13: Loans (non-current) | C13: ='Data-BS'!D12 -> 34 | D13: ='Data-BS'!E12 -> 16 | E13: ='Data-BS'!F12 -> 6 | F13: =D13-C13 -> -18 | G13: =IFERROR(F13/C13,"n.m.") -> -0.52941176 | H13: =E13-D13 -> -10 | I13: =IFERROR(H13/D13,"n.m.") -> -0.625
B14: Other financial assets (non-current) | C14: ='Data-BS'!D13 -> 3105 | D14: ='Data-BS'!E13 -> 3511 | E14: ='Data-BS'!F13 -> 2776 | F14: =D14-C14 -> 406 | G14: =IFERROR(F14/C14,"n.m.") -> 0.13075684 | H14: =E14-D14 -> -735 | I14: =IFERROR(H14/D14,"n.m.") -> -0.20934207
B15: Deferred tax assets (net) | C15: ='Data-BS'!D14 -> 454 | D15: ='Data-BS'!E14 -> 1108 | E15: ='Data-BS'!F14 -> 2264 | F15: =D15-C15 -> 654 | G15: =IFERROR(F15/C15,"n.m.") -> 1.4405286 | H15: =E15-D15 -> 1156 | I15: =IFERROR(H15/D15,"n.m.") -> 1.0433213
B16: Income tax assets (net) - non-current | C16: ='Data-BS'!D15 -> 3045 | D16: ='Data-BS'!E15 -> 1622 | E16: ='Data-BS'!F15 -> 666 | F16: =D16-C16 -> -1423 | G16: =IFERROR(F16/C16,"n.m.") -> -0.46732348 | H16: =E16-D16 -> -956 | I16: =IFERROR(H16/D16,"n.m.") -> -0.58939581
B17: Other non-current assets | C17: ='Data-BS'!D16 -> 2121 | D17: ='Data-BS'!E16 -> 2713 | E17: ='Data-BS'!F16 -> 3540 | F17: =D17-C17 -> 592 | G17: =IFERROR(F17/C17,"n.m.") -> 0.27911363 | H17: =E17-D17 -> 827 | I17: =IFERROR(H17/D17,"n.m.") -> 0.3048286
B18: Total non-current assets | C18: ='Data-BS'!D17 -> 48382 | D18: ='Data-BS'!E17 -> 51804 | E18: ='Data-BS'!F17 -> 52478 | F18: =D18-C18 -> 3422 | G18: =IFERROR(F18/C18,"n.m.") -> 0.070728783 | H18: =E18-D18 -> 674 | I18: =IFERROR(H18/D18,"n.m.") -> 0.013010578
B19: Current assets
B20: Current investments | C20: ='Data-BS'!D19 -> 12915 | D20: ='Data-BS'!E19 -> 12482 | E20: ='Data-BS'!F19 -> 12950 | F20: =D20-C20 -> -433 | G20: =IFERROR(F20/C20,"n.m.") -> -0.033526907 | H20: =E20-D20 -> 468 | I20: =IFERROR(H20/D20,"n.m.") -> 0.037493991
B21: Trade receivables | C21: ='Data-BS'!D20 -> 30193 | D21: ='Data-BS'!E20 -> 31158 | E21: ='Data-BS'!F20 -> 35234 | F21: =D21-C21 -> 965 | G21: =IFERROR(F21/C21,"n.m.") -> 0.031961051 | H21: =E21-D21 -> 4076 | I21: =IFERROR(H21/D21,"n.m.") -> 0.13081713
B22: Cash and cash equivalents | C22: ='Data-BS'!D21 -> 14786 | D22: ='Data-BS'!E21 -> 24455 | E22: ='Data-BS'!F21 -> 22201 | F22: =D22-C22 -> 9669 | G22: =IFERROR(F22/C22,"n.m.") -> 0.65392939 | H22: =E22-D22 -> -2254 | I22: =IFERROR(H22/D22,"n.m.") -> -0.092169291
B23: Loans (current) | C23: ='Data-BS'!D22 -> 248 | D23: ='Data-BS'!E22 -> 249 | E23: ='Data-BS'!F22 -> 234 | F23: =D23-C23 -> 1 | G23: =IFERROR(F23/C23,"n.m.") -> 0.0040322581 | H23: =E23-D23 -> -15 | I23: =IFERROR(H23/D23,"n.m.") -> -0.060240964
B24: Other financial assets (current) | C24: ='Data-BS'!D23 -> 12085 | D24: ='Data-BS'!E23 -> 13840 | E24: ='Data-BS'!F23 -> 15890 | F24: =D24-C24 -> 1755 | G24: =IFERROR(F24/C24,"n.m.") -> 0.14522135 | H24: =E24-D24 -> 2050 | I24: =IFERROR(H24/D24,"n.m.") -> 0.14812139
B25: Income tax assets (net) - current | C25: ='Data-BS'!D24 -> 6397 | D25: ='Data-BS'!E24 -> 2975 | E25: ='Data-BS'!F24 -> 1835 | F25: =D25-C25 -> -3422 | G25: =IFERROR(F25/C25,"n.m.") -> -0.53493825 | H25: =E25-D25 -> -1140 | I25: =IFERROR(H25/D25,"n.m.") -> -0.38319328
B26: Other current assets | C26: ='Data-BS'!D25 -> 12808 | D26: ='Data-BS'!E25 -> 11940 | E26: ='Data-BS'!F25 -> 15145 | F26: =D26-C26 -> -868 | G26: =IFERROR(F26/C26,"n.m.") -> -0.067770144 | H26: =E26-D26 -> 3205 | I26: =IFERROR(H26/D26,"n.m.") -> 0.26842546
B27: Total current assets | C27: ='Data-BS'!D26 -> 89432 | D27: ='Data-BS'!E26 -> 97099 | E27: ='Data-BS'!F26 -> 103489 | F27: =D27-C27 -> 7667 | G27: =IFERROR(F27/C27,"n.m.") -> 0.08572994 | H27: =E27-D27 -> 6390 | I27: =IFERROR(H27/D27,"n.m.") -> 0.065809123
B28: TOTAL ASSETS | C28: ='Data-BS'!D27 -> 137814 | D28: ='Data-BS'!E27 -> 148903 | E28: ='Data-BS'!F27 -> 155967 | F28: =D28-C28 -> 11089 | G28: =IFERROR(F28/C28,"n.m.") -> 0.080463523 | H28: =E28-D28 -> 7064 | I28: =IFERROR(H28/D28,"n.m.") -> 0.04744028
B29: EQUITY AND LIABILITIES
B30: Equity
B31: Equity share capital | C31: ='Data-BS'!D30 -> 2071 | D31: ='Data-BS'!E30 -> 2073 | E31: ='Data-BS'!F30 -> 2024 | F31: =D31-C31 -> 2 | G31: =IFERROR(F31/C31,"n.m.") -> 0.00096571704 | H31: =E31-D31 -> -49 | I31: =IFERROR(H31/D31,"n.m.") -> -0.023637241
B32: Other equity | C32: ='Data-BS'!D31 -> 86045 | D32: ='Data-BS'!E31 -> 93745 | E32: ='Data-BS'!F31 -> 90828 | F32: =D32-C32 -> 7700 | G32: =IFERROR(F32/C32,"n.m.") -> 0.089488059 | H32: =E32-D32 -> -2917 | I32: =IFERROR(H32/D32,"n.m.") -> -0.031116326
B33: Total equity attributable to owners | C33: ='Data-BS'!D32 -> 88116 | D33: ='Data-BS'!E32 -> 95818 | E33: ='Data-BS'!F32 -> 92852 | F33: =D33-C33 -> 7702 | G33: =IFERROR(F33/C33,"n.m.") -> 0.087407508 | H33: =E33-D33 -> -2966 | I33: =IFERROR(H33/D33,"n.m.") -> -0.030954518
B34: Non-controlling interests | C34: ='Data-BS'!D33 -> 345 | D34: ='Data-BS'!E33 -> 385 | E34: ='Data-BS'!F33 -> 445 | F34: =D34-C34 -> 40 | G34: =IFERROR(F34/C34,"n.m.") -> 0.11594203 | H34: =E34-D34 -> 60 | I34: =IFERROR(H34/D34,"n.m.") -> 0.15584416
B35: Total equity | C35: ='Data-BS'!D34 -> 88461 | D35: ='Data-BS'!E34 -> 96203 | E35: ='Data-BS'!F34 -> 93297 | F35: =D35-C35 -> 7742 | G35: =IFERROR(F35/C35,"n.m.") -> 0.087518794 | H35: =E35-D35 -> -2906 | I35: =IFERROR(H35/D35,"n.m.") -> -0.030206958
B36: Non-current liabilities
B37: Lease liabilities (non-current) | C37: ='Data-BS'!D36 -> 6400 | D37: ='Data-BS'!E36 -> 5772 | E37: ='Data-BS'!F36 -> 6016 | F37: =D37-C37 -> -628 | G37: =IFERROR(F37/C37,"n.m.") -> -0.098125 | H37: =E37-D37 -> 244 | I37: =IFERROR(H37/D37,"n.m.") -> 0.042273042
B38: Other financial liabilities (non-current) | C38: ='Data-BS'!D37 -> 2130 | D38: ='Data-BS'!E37 -> 2141 | E38: ='Data-BS'!F37 -> 2092 | F38: =D38-C38 -> 11 | G38: =IFERROR(F38/C38,"n.m.") -> 0.0051643192 | H38: =E38-D38 -> -49 | I38: =IFERROR(H38/D38,"n.m.") -> -0.022886502
B39: Deferred tax liabilities (net) | C39: ='Data-BS'!D38 -> 1794 | D39: ='Data-BS'!E38 -> 1722 | E39: ='Data-BS'!F38 -> 1679 | F39: =D39-C39 -> -72 | G39: =IFERROR(F39/C39,"n.m.") -> -0.040133779 | H39: =E39-D39 -> -43 | I39: =IFERROR(H39/D39,"n.m.") -> -0.024970964
B40: Other non-current liabilities | C40: ='Data-BS'!D39 -> 235 | D40: ='Data-BS'!E39 -> 215 | E40: ='Data-BS'!F39 -> 561 | F40: =D40-C40 -> -20 | G40: =IFERROR(F40/C40,"n.m.") -> -0.085106383 | H40: =E40-D40 -> 346 | I40: =IFERROR(H40/D40,"n.m.") -> 1.6093023
B41: Total non-current liabilities | C41: ='Data-BS'!D40 -> 10559 | D41: ='Data-BS'!E40 -> 9850 | E41: ='Data-BS'!F40 -> 10348 | F41: =D41-C41 -> -709 | G41: =IFERROR(F41/C41,"n.m.") -> -0.06714651 | H41: =E41-D41 -> 498 | I41: =IFERROR(H41/D41,"n.m.") -> 0.050558376
...

Sheet Comparative PL
A1: Comparative Statement of Profit & Loss — Infosys Limited (Consolidated)
B3: All ₹ in Crore. FY25 vs FY24 and FY26 vs FY25 shown side by side.
B4: Particulars | C4: FY2024 | D4: FY2025 | E4: FY2026 | F4: Change ₹ (FY25 vs FY24) | G4: Change % (FY25 vs FY24) | H4: Change ₹ (FY26 vs FY25) | I4: Change % (FY26 vs FY25)
B5: Revenue from operations | C5: ='Data-PL'!D4 -> 153670 | D5: ='Data-PL'!E4 -> 162990 | E5: ='Data-PL'!F4 -> 178650 | F5: =D5-C5 -> 9320 | G5: =IFERROR(F5/C5,"n.m.") -> 0.060649444 | H5: =E5-D5 -> 15660 | I5: =IFERROR(H5/D5,"n.m.") -> 0.096079514
B6: Other income, net | C6: ='Data-PL'!D5 -> 4711 | D6: ='Data-PL'!E5 -> 3600 | E6: ='Data-PL'!F5 -> 4322 | F6: =D6-C6 -> -1111 | G6: =IFERROR(F6/C6,"n.m.") -> -0.23583103 | H6: =E6-D6 -> 722 | I6: =IFERROR(H6/D6,"n.m.") -> 0.20055556
B7: Total income | C7: ='Data-PL'!D6 -> 158381 | D7: ='Data-PL'!E6 -> 166590 | E7: ='Data-PL'!F6 -> 182972 | F7: =D7-C7 -> 8209 | G7: =IFERROR(F7/C7,"n.m.") -> 0.051830712 | H7: =E7-D7 -> 16382 | I7: =IFERROR(H7/D7,"n.m.") -> 0.098337235
B8: EXPENSES
B9: Employee benefit expenses | C9: ='Data-PL'!D8 -> 82620 | D9: ='Data-PL'!E8 -> 85950 | E9: ='Data-PL'!F8 -> 95094 | F9: =D9-C9 -> 3330 | G9: =IFERROR(F9/C9,"n.m.") -> 0.040305011 | H9: =E9-D9 -> 9144 | I9: =IFERROR(H9/D9,"n.m.") -> 0.10638743
B10: Cost of technical sub-contractors | C10: ='Data-PL'!D9 -> 12232 | D10: ='Data-PL'!E9 -> 12937 | E10: ='Data-PL'!F9 -> 15421 | F10: =D10-C10 -> 705 | G10: =IFERROR(F10/C10,"n.m.") -> 0.05763571 | H10: =E10-D10 -> 2484 | I10: =IFERROR(H10/D10,"n.m.") -> 0.19200742
B11: Travel expenses | C11: ='Data-PL'!D10 -> 1759 | D11: ='Data-PL'!E10 -> 1894 | E11: ='Data-PL'!F10 -> 2097 | F11: =D11-C11 -> 135 | G11: =IFERROR(F11/C11,"n.m.") -> 0.076748152 | H11: =E11-D11 -> 203 | I11: =IFERROR(H11/D11,"n.m.") -> 0.10718057
B12: Cost of software packages and others | C12: ='Data-PL'!D11 -> 13515 | D12: ='Data-PL'!E11 -> 15911 | E12: ='Data-PL'!F11 -> 15722 | F12: =D12-C12 -> 2396 | G12: =IFERROR(F12/C12,"n.m.") -> 0.1772845 | H12: =E12-D12 -> -189 | I12: =IFERROR(H12/D12,"n.m.") -> -0.011878575
B13: Communication expenses | C13: ='Data-PL'!D12 -> 677 | D13: ='Data-PL'!E12 -> 620 | E13: ='Data-PL'!F12 -> 603 | F13: =D13-C13 -> -57 | G13: =IFERROR(F13/C13,"n.m.") -> -0.084194978 | H13: =E13-D13 -> -17 | I13: =IFERROR(H13/D13,"n.m.") -> -0.027419355
B14: Consultancy and professional charges | C14: ='Data-PL'!D13 -> 1726 | D14: ='Data-PL'!E13 -> 1655 | E14: ='Data-PL'!F13 -> 2090 | F14: =D14-C14 -> -71 | G14: =IFERROR(F14/C14,"n.m.") -> -0.041135574 | H14: =E14-D14 -> 435 | I14: =IFERROR(H14/D14,"n.m.") -> 0.26283988
B15: Depreciation and amortization expenses | C15: ='Data-PL'!D14 -> 4678 | D15: ='Data-PL'!E14 -> 4812 | E15: ='Data-PL'!F14 -> 4902 | F15: =D15-C15 -> 134 | G15: =IFERROR(F15/C15,"n.m.") -> 0.02864472 | H15: =E15-D15 -> 90 | I15: =IFERROR(H15/D15,"n.m.") -> 0.018703242
B16: Finance cost | C16: ='Data-PL'!D15 -> 470 | D16: ='Data-PL'!E15 -> 416 | E16: ='Data-PL'!F15 -> 416 | F16: =D16-C16 -> -54 | G16: =IFERROR(F16/C16,"n.m.") -> -0.11489362 | H16: =E16-D16 -> 0 | I16: =IFERROR(H16/D16,"n.m.") -> 0
B17: Other expenses | C17: ='Data-PL'!D16 -> 4716 | D17: ='Data-PL'!E16 -> 4787 | E17: ='Data-PL'!F16 -> 5343 | F17: =D17-C17 -> 71 | G17: =IFERROR(F17/C17,"n.m.") -> 0.015055131 | H17: =E17-D17 -> 556 | I17: =IFERROR(H17/D17,"n.m.") -> 0.1161479
B18: Total expenses | C18: ='Data-PL'!D17 -> 122393 | D18: ='Data-PL'!E17 -> 128982 | E18: ='Data-PL'!F17 -> 141688 | F18: =D18-C18 -> 6589 | G18: =IFERROR(F18/C18,"n.m.") -> 0.053834778 | H18: =E18-D18 -> 12706 | I18: =IFERROR(H18/D18,"n.m.") -> 0.09850987
B19: Profit before exceptional item and tax | C19: ='Data-PL'!D18 -> 35988 | D19: ='Data-PL'!E18 -> 37608 | E19: ='Data-PL'!F18 -> 41284 | F19: =D19-C19 -> 1620 | G19: =IFERROR(F19/C19,"n.m.") -> 0.045015005 | H19: =E19-D19 -> 3676 | I19: =IFERROR(H19/D19,"n.m.") -> 0.097745161
B20: Exceptional item (Impact of Labour Codes) | C20: ='Data-PL'!D19 -> 0 | D20: ='Data-PL'!E19 -> 0 | E20: ='Data-PL'!F19 -> 1289 | F20: =D20-C20 -> 0 | G20: =IFERROR(F20/C20,"n.m.") -> n.m. | H20: =E20-D20 -> 1289 | I20: =IFERROR(H20/D20,"n.m.") -> n.m.
... B25: Profit for the year | C25: ='Data-PL'!D24 -> 26248 | D25: ='Data-PL'!E24 -> 26750 | E25: ='Data-PL'!F24 -> 29474 | F25: =D25-C25 -> 502 | G25: =IFERROR(F25/C25,"n.m.") -> 0.019125267 | H25: =E25-D25 -> 2724 | I25: =IFERROR(H25/D25,"n.m.") -> 0.10183178
B27: Observations:
B28: • Revenue grew 6.1% in FY25 and accelerated to 9.6% in FY26, the strongest growth in three years, aided by large-deal ramp-ups and AI-led services.
B29: • Employee costs grew broadly in line with revenue (+4.0% FY25, +10.6% FY26), keeping the cost structure stable; cost of technical sub-contractors rose faster (+19.2% FY26), suggesting greater reliance on subcontracted delivery to meet demand.
B30: • Profit before tax grew 4.5% in FY25 but only 6.4% in FY26 net of a one-off ₹1,289 crore exceptional charge relating to the Indian Labour Codes; pre-exceptional PBT actually grew 9.8%, a cleaner read of underlying operating performance.
B31: • Net profit for the year rose 1.9% in FY25 and 10.2% in FY26, aided by a lower effective tax rate in FY26 (26.3% vs 28.9% in FY25) from higher deferred-tax credits.

Sheet Common-Size BS
A1: Common-Size Balance Sheet — Infosys Limited (Consolidated)
B3: Each line as % of Total Assets for that year (₹ columns link to Data-BS).
B4: Particulars | C4: FY2024 ₹Cr | D4: FY2025 ₹Cr | E4: FY2026 ₹Cr | F4: FY2024 % | G4: FY2025 % | H4: FY2026 %
B5: ASSETS
B6: Non-current assets
B7: Property, plant and equipment | C7: ='Data-BS'!D6 -> 12370 | D7: ='Data-BS'!E6 -> 11778 | E7: ='Data-BS'!F6 -> 12651 | F7: =C7/C28 -> 0.08975866 | G7: =D7/D28 -> 0.079098474 | H7: =E7/E28 -> 0.081113312
B8: Right-of-use assets | C8: ='Data-BS'!D7 -> 6552 | D8: ='Data-BS'!E7 -> 6311 | E8: ='Data-BS'!F7 -> 6177 | F8: =C8/C28 -> 0.04754234 | G8: =D8/D28 -> 0.042383297 | H8: =E8/E28 -> 0.039604532
B9: Capital work-in-progress | C9: ='Data-BS'!D8 -> 293 | D9: ='Data-BS'!E8 -> 814 | E9: ='Data-BS'!F8 -> 526 | F9: =C9/C28 -> 0.002126054 | G9: =D9/D28 -> 0.0054666461 | H9: =E9/E28 -> 0.0033725083
B10: Goodwill | C10: ='Data-BS'!D9 -> 7303 | D10: ='Data-BS'!E9 -> 10106 | E10: ='Data-BS'!F9 -> 12117 | F10: =C10/C28 -> 0.052991713 | G10: =D10/D28 -> 0.067869687 | H10: =E10/E28 -> 0.077689511
B11: Other intangible assets | C11: ='Data-BS'!D10 -> 1397 | D11: ='Data-BS'!E10 -> 2766 | E11: ='Data-BS'!F10 -> 2825 | F11: =C11/C28 -> 0.010136851 | G11: =D11/D28 -> 0.018575851 | H11: =E11/E28 -> 0.018112806
B12: Non-current investments | C12: ='Data-BS'!D11 -> 11708 | D12: ='Data-BS'!E11 -> 11059 | E12: ='Data-BS'!F11 -> 8930 | F12: =C12/C28 -> 0.084955084 | G12: =D12/D28 -> 0.074269827 | H12: =E12/E28 -> 0.057255702
B13: Loans (non-current) | C13: ='Data-BS'!D12 -> 34 | D13: ='Data-BS'!E12 -> 16 | E13: ='Data-BS'!F12 -> 6 | F13: =C13/C28 -> 0.00024670933 | G13: =D13/D28 -> 0.0001074525 | H13: =E13/E28 -> 3.8469676e-05
B14: Other financial assets (non-current) | C14: ='Data-BS'!D13 -> 3105 | D14: ='Data-BS'!E13 -> 3511 | E14: ='Data-BS'!F13 -> 2776 | F14: =C14/C28 -> 0.022530367 | G14: =D14/D28 -> 0.023579109 | H14: =E14/E28 -> 0.017798637
B15: Deferred tax assets (net) | C15: ='Data-BS'!D14 -> 454 | D15: ='Data-BS'!E14 -> 1108 | E15: ='Data-BS'!F14 -> 2264 | F15: =C15/C28 -> 0.0032942952 | G15: =D15/D28 -> 0.0074410858 | H15: =E15/E28 -> 0.014515891
B16: Income tax assets (net) - non-current | C16: ='Data-BS'!D15 -> 3045 | D16: ='Data-BS'!E15 -> 1622 | E16: ='Data-BS'!F15 -> 666 | F16: =C16/C28 -> 0.022094998 | G16: =D16/D28 -> 0.010892997 | H16: =E16/E28 -> 0.0042701341
B17: Other non-current assets | C17: ='Data-BS'!D16 -> 2121 | D17: ='Data-BS'!E16 -> 2713 | E17: ='Data-BS'!F16 -> 3540 | F17: =C17/C28 -> 0.015390309 | G17: =D17/D28 -> 0.018219915 | H17: =E17/E28 -> 0.022697109
B18: Total non-current assets | C18: ='Data-BS'!D17 -> 48382 | D18: ='Data-BS'!E17 -> 51804 | E18: ='Data-BS'!F17 -> 52478 | F18: =C18/C28 -> 0.35106738 | G18: =D18/D28 -> 0.34790434 | H18: =E18/E28 -> 0.33646861
B19: Current assets
B20: Current investments | C20: ='Data-BS'!D19 -> 12915 | D20: ='Data-BS'!E19 -> 12482 | E20: ='Data-BS'!F19 -> 12950 | F20: =C20/C28 -> 0.093713266 | G20: =D20/D28 -> 0.083826384 | H20: =E20/E28 -> 0.083030385
B21: Trade receivables | C21: ='Data-BS'!D20 -> 30193 | D21: ='Data-BS'!E20 -> 31158 | E21: ='Data-BS'!F20 -> 35234 | F21: =C21/C28 -> 0.21908514 | G21: =D21/D28 -> 0.20925032 | H21: =E21/E28 -> 0.22590676
B22: Cash and cash equivalents | C22: ='Data-BS'!D21 -> 14786 | D22: ='Data-BS'!E21 -> 24455 | E22: ='Data-BS'!F21 -> 22201 | F22: =C22/C28 -> 0.10728954 | G22: =D22/D28 -> 0.16423443 | H22: =E22/E28 -> 0.14234421
B23: Loans (current) | C23: ='Data-BS'!D22 -> 248 | D23: ='Data-BS'!E22 -> 249 | E23: ='Data-BS'!F22 -> 234 | F23: =C23/C28 -> 0.0017995269 | G23: =D23/D28 -> 0.0016722296 | H23: =E23/E28 -> 0.0015003174
B24: Other financial assets (current) | C24: ='Data-BS'!D23 -> 12085 | D24: ='Data-BS'!E23 -> 13840 | E24: ='Data-BS'!F23 -> 15890 | F24: =C24/C28 -> 0.087690656 | G24: =D24/D28 -> 0.092946415 | H24: =E24/E28 -> 0.10188053
B25: Income tax assets (net) - current | C25: ='Data-BS'!D24 -> 6397 | D25: ='Data-BS'!E24 -> 2975 | E25: ='Data-BS'!F24 -> 1835 | F25: =C25/C28 -> 0.046417635 | G25: =D25/D28 -> 0.01997945 | H25: =E25/E28 -> 0.011765309
B26: Other current assets | C26: ='Data-BS'!D25 -> 12808 | D26: ='Data-BS'!E25 -> 11940 | E26: ='Data-BS'!F25 -> 15145 | F26: =C26/C28 -> 0.092936857 | G26: =D26/D28 -> 0.08018643 | H26: =E26/E28 -> 0.097103875
B27: Total current assets | C27: ='Data-BS'!D26 -> 89432 | D27: ='Data-BS'!E26 -> 97099 | E27: ='Data-BS'!F26 -> 103489 | F27: =C27/C28 -> 0.64893262 | G27: =D27/D28 -> 0.65209566 | H27: =E27/E28 -> 0.66353139
B28: TOTAL ASSETS | C28: ='Data-BS'!D27 -> 137814 | D28: ='Data-BS'!E27 -> 148903 | E28: ='Data-BS'!F27 -> 155967 | F28: =C28/C28 -> 1 | G28: =D28/D28 -> 1 | H28: =E28/E28 -> 1
B29: EQUITY AND LIABILITIES
B30: Equity
B31: Equity share capital | C31: ='Data-BS'!D30 -> 2071 | D31: ='Data-BS'!E30 -> 2073 | E31: ='Data-BS'!F30 -> 2024 | F31: =C31/C28 -> 0.015027501 | G31: =D31/D28 -> 0.013921815 | H31: =E31/E28 -> 0.012977104
B32: Other equity | C32: ='Data-BS'!D31 -> 86045 | D32: ='Data-BS'!E31 -> 93745 | E32: ='Data-BS'!F31 -> 90828 | F32: =C32/C28 -> 0.62435602 | G32: =D32/D28 -> 0.62957093 | H32: =E32/E28 -> 0.58235396
B33: Total equity attributable to owners | C33: ='Data-BS'!D32 -> 88116 | D33: ='Data-BS'!E32 -> 95818 | E33: ='Data-BS'!F32 -> 92852 | F33: =C33/C28 -> 0.63938352 | G33: =D33/D28 -> 0.64349274 | H33: =E33/E28 -> 0.59533106
B34: Non-controlling interests | C34: ='Data-BS'!D33 -> 345 | D34: ='Data-BS'!E33 -> 385 | E34: ='Data-BS'!F33 -> 445 | F34: =C34/C28 -> 0.0025033741 | G34: =D34/D28 -> 0.0025855758 | H34: =E34/E28 -> 0.0028531677
B35: Total equity | C35: ='Data-BS'!D34 -> 88461 | D35: ='Data-BS'!E34 -> 96203 | E35: ='Data-BS'!F34 -> 93297 | F35: =C35/C28 -> 0.64188689 | G35: =D35/D28 -> 0.64607832 | H35: =E35/E28 -> 0.59818423
B36: Non-current liabilities
B37: Lease liabilities (non-current) | C37: ='Data-BS'!D36 -> 6400 | D37: ='Data-BS'!E36 -> 5772 | E37: ='Data-BS'!F36 -> 6016 | F37: =C37/C28 -> 0.046439404 | G37: =D37/D28 -> 0.03876349 | H37: =E37/E28 -> 0.038572262
B38: Other financial liabilities (non-current) | C38: ='Data-BS'!D37 -> 2130 | D38: ='Data-BS'!E37 -> 2141 | E38: ='Data-BS'!F37 -> 2092 | F38: =C38/C28 -> 0.015455614 | G38: =D38/D28 -> 0.014378488 | H38: =E38/E28 -> 0.013413094
B39: Deferred tax liabilities (net) | C39: ='Data-BS'!D38 -> 1794 | D39: ='Data-BS'!E38 -> 1722 | E39: ='Data-BS'!F38 -> 1679 | F39: =C39/C28 -> 0.013017545 | G39: =D39/D28 -> 0.011564576 | H39: =E39/E28 -> 0.010765098
B40: Other non-current liabilities | C40: ='Data-BS'!D39 -> 235 | D40: ='Data-BS'!E39 -> 215 | E40: ='Data-BS'!F39 -> 561 | F40: =C40/C28 -> 0.0017051969 | G40: =D40/D28 -> 0.001443893 | H40: =E40/E28 -> 0.0035969147
B41: Total non-current liabilities | C41: ='Data-BS'!D40 -> 10559 | D41: ='Data-BS'!E40 -> 9850 | E41: ='Data-BS'!F40 -> 10348 | F41: =C41/C28 -> 0.07661776 | G41: =D41/D28 -> 0.066150447 | H41: =E41/E28 -> 0.066347368
...

Sheet Common-Size PL
A1: Common-Size Statement of Profit & Loss — Infosys Limited (Consolidated)
B3: Each line as % of Revenue from operations for that year (₹ columns link to Data-PL).
B4: Particulars | C4: FY2024 ₹Cr | D4: FY2025 ₹Cr | E4: FY2026 ₹Cr | F4: FY2024 % | G4: FY2025 % | H4: FY2026 %
B5: Revenue from operations | C5: ='Data-PL'!D4 -> 153670 | D5: ='Data-PL'!E4 -> 162990 | E5: ='Data-PL'!F4 -> 178650 | F5: =C5/C5 -> 1 | G5: =D5/D5 -> 1 | H5: =E5/E5 -> 1
B6: Other income, net | C6: ='Data-PL'!D5 -> 4711 | D6: ='Data-PL'!E5 -> 3600 | E6: ='Data-PL'!F5 -> 4322 | F6: =C6/C5 -> 0.030656602 | G6: =D6/D5 -> 0.022087245 | H6: =E6/E5 -> 0.024192555
B7: Total income | C7: ='Data-PL'!D6 -> 158381 | D7: ='Data-PL'!E6 -> 166590 | E7: ='Data-PL'!F6 -> 182972 | F7: =C7/C5 -> 1.0306566 | G7: =D7/D5 -> 1.0220872 | H7: =E7/E5 -> 1.0241926
B8: EXPENSES
B9: Employee benefit expenses | C9: ='Data-PL'!D8 -> 82620 | D9: ='Data-PL'!E8 -> 85950 | E9: ='Data-PL'!F8 -> 95094 | F9: =C9/C5 -> 0.5376456 | G9: =D9/D5 -> 0.52733297 | H9: =E9/E5 -> 0.53229219
B10: Cost of technical sub-contractors | C10: ='Data-PL'!D9 -> 12232 | D10: ='Data-PL'!E9 -> 12937 | E10: ='Data-PL'!F9 -> 15421 | F10: =C10/C5 -> 0.079599141 | G10: =D10/D5 -> 0.079372968 | H10: =E10/E5 -> 0.086319619
B11: Travel expenses | C11: ='Data-PL'!D10 -> 1759 | D11: ='Data-PL'!E10 -> 1894 | E11: ='Data-PL'!F10 -> 2097 | F11: =C11/C5 -> 0.011446606 | G11: =D11/D5 -> 0.011620345 | H11: =E11/E5 -> 0.011738035
B12: Cost of software packages and others | C12: ='Data-PL'!D11 -> 13515 | D12: ='Data-PL'!E11 -> 15911 | E12: ='Data-PL'!F11 -> 15722 | F12: =C12/C5 -> 0.087948201 | G12: =D12/D5 -> 0.097619486 | H12: =E12/E5 -> 0.088004478
B13: Communication expenses | C13: ='Data-PL'!D12 -> 677 | D13: ='Data-PL'!E12 -> 620 | E13: ='Data-PL'!F12 -> 603 | F13: =C13/C5 -> 0.0044055443 | G13: =D13/D5 -> 0.0038039144 | H13: =E13/E5 -> 0.0033753149
B14: Consultancy and professional charges | C14: ='Data-PL'!D13 -> 1726 | D14: ='Data-PL'!E13 -> 1655 | E14: ='Data-PL'!F13 -> 2090 | F14: =C14/C5 -> 0.01123186 | G14: =D14/D5 -> 0.010153997 | H14: =E14/E5 -> 0.011698853
B15: Depreciation and amortization expenses | C15: ='Data-PL'!D14 -> 4678 | D15: ='Data-PL'!E14 -> 4812 | E15: ='Data-PL'!F14 -> 4902 | F15: =C15/C5 -> 0.030441856 | G15: =D15/D5 -> 0.029523284 | H15: =E15/E5 -> 0.027439127
B16: Finance cost | C16: ='Data-PL'!D15 -> 470 | D16: ='Data-PL'!E15 -> 416 | E16: ='Data-PL'!F15 -> 416 | F16: =C16/C5 -> 0.003058502 | G16: =D16/D5 -> 0.0025523038 | H16: =E16/E5 -> 0.0023285754
B17: Other expenses | C17: ='Data-PL'!D16 -> 4716 | D17: ='Data-PL'!E16 -> 4787 | E17: ='Data-PL'!F16 -> 5343 | F17: =C17/C5 -> 0.030689139 | G17: =D17/D5 -> 0.0293699 | H17: =E17/E5 -> 0.029907641
B18: Total expenses | C18: ='Data-PL'!D17 -> 122393 | D18: ='Data-PL'!E17 -> 128982 | E18: ='Data-PL'!F17 -> 141688 | F18: =C18/C5 -> 0.79646645 | G18: =D18/D5 -> 0.79134916 | H18: =E18/E5 -> 0.79310383
B19: Profit before exceptional item and tax | C19: ='Data-PL'!D18 -> 35988 | D19: ='Data-PL'!E18 -> 37608 | E19: ='Data-PL'!F18 -> 41284 | F19: =C19/C5 -> 0.23419015 | G19: =D19/D5 -> 0.23073808 | H19: =E19/E5 -> 0.23108872
B20: Exceptional item (Impact of Labour Codes) | C20: ='Data-PL'!D19 -> 0 | D20: ='Data-PL'!E19 -> 0 | E20: ='Data-PL'!F19 -> 1289 | F20: =C20/C5 -> 0 | G20: =D20/D5 -> 0 | H20: =E20/E5 -> 0.0072152253
B21: Profit before tax | C21: ='Data-PL'!D20 -> 35988 | D21: ='Data-PL'!E20 -> 37608 | E21: ='Data-PL'!F20 -> 39995 | F21: =C21/C5 -> 0.23419015 | G21: =D21/D5 -> 0.23073808 | H21: =E21/E5 -> 0.2238735
B22: Total tax expense | C22: ='Data-PL'!D23 -> 9740 | D22: ='Data-PL'!E23 -> 10858 | E22: ='Data-PL'!F23 -> 10521 | F22: =C22/C5 -> 0.063382573 | G22: =D22/D5 -> 0.066617584 | H22: =E22/E5 -> 0.058891688
B23: Profit for the year | C23: ='Data-PL'!D24 -> 26248 | D23: ='Data-PL'!E24 -> 26750 | E23: ='Data-PL'!F24 -> 29474 | F23: =C23/C5 -> 0.17080757 | G23: =D23/D5 -> 0.1641205 | H23: =E23/E5 -> 0.16498181
B25: Observations:
B26: • Employee benefit expenses are consistently the largest cost line, but its share of revenue has been declining — 53.8% (FY24) → 52.7% (FY25) → 53.2% (FY26) — indicating broadly stable but not dramatically improving cost efficiency (offshore/onsite mix, pyramid management, utilization).
B27: • Cost of technical sub-contractors rose from 8.0% to 8.6% of revenue over the period, indicating growing use of subcontracted delivery capacity as demand recovered — a flexible cost but typically at a margin premium versus internal staffing.
B28: • Net profit margin (Profit for the year / Revenue) moved from 17.1% (FY24) to 16.4% (FY25) to 16.5% (FY26) — broadly stable, with FY26 held back ~0.7pp by the one-off Labour Codes exceptional item; pre-exceptional net margin would be closer to 17.2%, a genuine improvement.
B29: • Finance cost as % of revenue is negligible and falling (0.31% → 0.26% → 0.23%), consistent with the company's debt-free balance sheet — the small charge is almost entirely the interest cost on lease liabilities under Ind AS 116.

Sheet Trend Analysis
A1: Trend Analysis — Infosys Limited (Index, FY2024 = 100)
B3: Each metric indexed to FY2024 = 100 to show relative growth over the 3-year window.
B4: Metric | C4: FY2024 ₹Cr | D4: FY2025 ₹Cr | E4: FY2026 ₹Cr | F4: Index FY24 | G4: Index FY25 | H4: Index FY26
B5: Revenue from operations | C5: ='Data-PL'!D4 -> 153670 | D5: ='Data-PL'!E4 -> 162990 | E5: ='Data-PL'!F4 -> 178650 | F5: =C5/C5*100 -> 100 | G5: =D5/C5*100 -> 106.06494 | H5: =E5/C5*100 -> 116.25561
B6: Total income | C6: ='Data-PL'!D6 -> 158381 | D6: ='Data-PL'!E6 -> 166590 | E6: ='Data-PL'!F6 -> 182972 | F6: =C6/C6*100 -> 100 | G6: =D6/C6*100 -> 105.18307 | H6: =E6/C6*100 -> 115.52648
B7: Profit before tax | C7: ='Data-PL'!D20 -> 35988 | D7: ='Data-PL'!E20 -> 37608 | E7: ='Data-PL'!F20 -> 39995 | F7: =C7/C7*100 -> 100 | G7: =D7/C7*100 -> 104.5015 | H7: =E7/C7*100 -> 111.13427
B8: Profit for the year | C8: ='Data-PL'!D24 -> 26248 | D8: ='Data-PL'!E24 -> 26750 | E8: ='Data-PL'!F24 -> 29474 | F8: =C8/C8*100 -> 100 | G8: =D8/C8*100 -> 101.91253 | H8: =E8/C8*100 -> 112.29046
B9: Total assets | C9: ='Data-BS'!D27 -> 137814 | D9: ='Data-BS'!E27 -> 148903 | E9: ='Data-BS'!F27 -> 155967 | F9: =C9/C9*100 -> 100 | G9: =D9/C9*100 -> 108.04635 | H9: =E9/C9*100 -> 113.1721
B10: Total equity | C10: ='Data-BS'!D34 -> 88461 | D10: ='Data-BS'!E34 -> 96203 | E10: ='Data-BS'!F34 -> 93297 | F10: =C10/C10*100 -> 100 | G10: =D10/C10*100 -> 108.75188 | H10: =E10/C10*100 -> 105.46682
B11: Trade receivables | C11: ='Data-BS'!D20 -> 30193 | D11: ='Data-BS'!E20 -> 31158 | E11: ='Data-BS'!F20 -> 35234 | F11: =C11/C11*100 -> 100 | G11: =D11/C11*100 -> 103.19611 | H11: =E11/C11*100 -> 116.69592
B12: Cash and cash equivalents | C12: ='Data-BS'!D21 -> 14786 | D12: ='Data-BS'!E21 -> 24455 | E12: ='Data-BS'!F21 -> 22201 | F12: =C12/C12*100 -> 100 | G12: =D12/C12*100 -> 165.39294 | H12: =E12/C12*100 -> 150.14879
B13: Net cash from operating activities (CFO) | C13: ='Data-CF'!C4 -> 25210 | D13: ='Data-CF'!D4 -> 35694 | E13: ='Data-CF'!E4 -> 33986 | F13: =C13/C13*100 -> 100 | G13: =D13/C13*100 -> 141.58667 | H13: =E13/C13*100 -> 134.81158
B14: EPS — Basic (₹) | C14: ='Data-PL'!D27 -> 63.39 | D14: ='Data-PL'!E27 -> 64.5 | E14: ='Data-PL'!F27 -> 71.58 | F14: =C14/C14*100 -> 100 | G14: =D14/C14*100 -> 101.75106 | H14: =E14/C14*100 -> 112.92002
B16: Observations:
B17: • Revenue index rose from 100 (FY24) to 106.1 (FY25) to 116.3 (FY26) — growth clearly accelerated in the third year, the strongest trend signal in the dataset.
B18: • Profit for the year (100 → 101.9 → 112.3) trails revenue growth slightly through FY25 then catches up in FY26, showing operating leverage returning after a flattish FY25.
B19: • Cash and cash equivalents show the most volatile trend (100 → 165.4 → 150.2) — a spike in FY25 from strong free cash flow, partly unwound in FY26 through the ₹18,058 crore buyback and continued high dividend payout.
B20: • EPS trend (100 → 101.8 → 112.9) tracks profit growth closely in FY24-25 but outpaces it in FY26 (net profit index 112.3 vs EPS index 112.9) because the share buyback reduced the weighted-average share count, giving a small per-share uplift on top of underlying profit growth.

Sheet Predictability Scores
A1: Predictability Scores — Altman Z-Score & Beneish M-Score (Infosys, Consolidated)
B3: Both models were designed for manufacturing / GAAP-reporting companies with inventory and are applied here as general-purpose screening tools for an asset-light IT-services firm — component definitions are adapted where noted, and results should be read as one input among several, not a standalone verdict.
B5: A. ALTMAN Z-SCORE (Original 1968 public-firm model)
B6: Component | D6: FY2024 | E6: FY2025 | F6: FY2026 | G6: Definition / Note
B7: Market value of equity (proxy, current — Aug-2026, held constant across FY24-26*) | D7: =Assumptions!$D$48 -> 481712 | E7: =Assumptions!$D$48 -> 481712 | F7: =Assumptions!$D$48 -> 481712 | G7: Links to Market Cap computed on the DCF Assumptions sheet (current price × diluted shares). *Historical period-end market caps for FY24/FY25 were not in scope; using the current value means FY24/FY25 Z-scores should be read as illustrative of the accounting-driven components only — FY26 is the representative estimate.
B8: X1 = Working Capital / Total Assets | D8: =('Data-BS'!D26-'Data-BS'!D48)/'Data-BS'!D27 -> 0.36743727 | E8: =('Data-BS'!E26-'Data-BS'!E48)/'Data-BS'!E27 -> 0.36432443 | F8: =('Data-BS'!F26-'Data-BS'!F48)/'Data-BS'!F27 -> 0.32806299 | G8: Working capital = Current Assets − Current Liabilities.
B9: X2 = Retained Earnings* / Total Assets | D9: ='Data-BS'!D31/'Data-BS'!D27 -> 0.62435602 | E9: ='Data-BS'!E31/'Data-BS'!E27 -> 0.62957093 | F9: ='Data-BS'!F31/'Data-BS'!F27 -> 0.58235396 | G9: *'Other equity' (reserves & retained earnings combined) used as proxy — Infosys does not separately disclose a stand-alone retained-earnings figure in the summarized consolidated balance sheet.
B10: X3 = EBIT / Total Assets | D10: =('Data-PL'!D18+'Data-PL'!D15-'Data-PL'!D5)/'Data-BS'!D27 -> 0.23036121 | E10: =('Data-PL'!E18+'Data-PL'!E15-'Data-PL'!E5)/'Data-BS'!E27 -> 0.23118406 | F10: =('Data-PL'!F18+'Data-PL'!F15-'Data-PL'!F5)/'Data-BS'!F27 -> 0.23965326 | G10: EBIT = Pre-exceptional PBT + Finance cost − Other income (consistent with Ratio Analysis sheet definition).
B11: X4 = Market Value of Equity / Total Liabilities | D11: =D7/('Data-BS'!D40+'Data-BS'!D48) -> 9.7605414 | E11: =D7/('Data-BS'!E40+'Data-BS'!E48) -> 9.1406452 | F11: =D7/('Data-BS'!F40+'Data-BS'!F48) -> 7.6864848 | G11: Total liabilities = Total non-current + Total current liabilities (excludes equity).
B12: X5 = Sales (Revenue) / Total Assets | D12: ='Data-PL'!D4/'Data-BS'!D27 -> 1.1150536 | E12: ='Data-PL'!E4/'Data-BS'!E27 -> 1.0946052 | F12: ='Data-PL'!F4/'Data-BS'!F27 -> 1.1454346 | G12: Asset turnover component.
B13: Altman Z-Score = 1.2·X1 + 1.4·X2 + 3.3·X3 + 0.6·X4 + 1.0·X5 | D13: =1.2*D8+1.4*D9+3.3*D10+0.6*D11+1*D12 -> 9.0465936 | E13: =1.2*E8+1.4*E9+3.3*E10+0.6*E11+1*E12 -> 8.6604883 | F13: =1.2*F8+1.4*F9+3.3*F10+0.6*F11+1*F12 -> 7.7571524 | G13: Zones: Z > 2.99 = Safe zone (low bankruptcy risk); 1.81 ≤ Z ≤ 2.99 = Grey zone; Z < 1.81 = Distress zone.
B14: Zone | D14: =IF(D13>2.99,"SAFE ZONE",IF(D13>=1.81,"GREY ZONE","DISTRESS ZONE")) -> SAFE ZONE | E14: =IF(E13>2.99,"SAFE ZONE",IF(E13>=1.81,"GREY ZONE","DISTRESS ZONE")) -> SAFE ZONE | F14: =IF(F13>2.99,"SAFE ZONE",IF(F13>=1.81,"GREY ZONE","DISTRESS ZONE")) -> SAFE ZONE
B16: Interpretation: Infosys' Altman Z-Score sits deep in the 'Safe' zone across all three years (typically 6-8x, far above the 2.99 threshold) — driven mainly by very high asset turnover (X5) and a debt-light, equity-funded balance sheet (X4), both structurally common to large IT-services exporters. The score should be read directionally rather than literally: the original model was calibrated on 1960s-70s US manufacturers, so an asset-light services company will almost always screen as very safe on this test. It is best used here to confirm the complete absence of near-term financial distress signals, which is consistent with every other ratio in this workbook (negligible leverage, strong liquidity, high interest coverage).
B21: B. BENEISH M-SCORE (Earnings-manipulation risk — FY25 vs FY26)
B22: Component | F22: Index Value (FY26 vs FY25) | G22: Interpretation
B23: DSRI — Days' Sales in Receivables Index | F23: =('Data-BS'!F20/'Data-PL'!F4)/('Data-BS'!E20/'Data-PL'!E4) -> 1.0316926 | G23: >1 means receivables grew faster than sales — a possible revenue-recognition red flag.
B24: GMI — Gross Margin Index | F24: =(('Data-PL'!E4-'Data-PL'!E8-'Data-PL'!E9-'Data-PL'!E11)/'Data-PL'!E4)/(('Data-PL'!F4-'Data-PL'!F8-'Data-PL'!F9-'Data-PL'!F11)/'Data-PL'!F4) -> 1.0078084 | G24: >1 means gross margin deteriorated y/y (prior-year margin higher) — creates incentive to manipulate earnings.
B25: AQI — Asset Quality Index | F25: =(1-('Data-BS'!E26+'Data-BS'!E6)/'Data-BS'!E27)/(1-('Data-BS'!F26+'Data-BS'!F6)/'Data-BS'!F27) -> 1.0526739 | G25: >1 means a growing share of assets sit outside current assets & PP&E (e.g., intangibles/goodwill) — potential for deferred cost capitalization.
B26: SGI — Sales Growth Index | F26: ='Data-PL'!F4/'Data-PL'!E4 -> 1.0960795 | G26: High sales growth (>1) is not itself a red flag, but fast-growing firms face more pressure to sustain reported growth, which the model treats as elevated (not necessarily fraudulent) risk.
B27: DEPI — Depreciation Index | F27: =('Data-PL'!E14/('Data-PL'!E14+'Data-BS'!E6))/('Data-PL'!F14/('Data-PL'!F14+'Data-BS'!F6)) -> 1.0386214 | G27: >1 means the depreciation rate slowed in the current year (assets depreciated more slowly) — could indicate useful lives were stretched to lift reported income.
B28: SGAI — SG&A Index | F28: =(('Data-PL'!F12+'Data-PL'!F13+'Data-PL'!F16)/'Data-PL'!F4)/(('Data-PL'!E12+'Data-PL'!E13+'Data-PL'!E16)/'Data-PL'!E4) -> 1.038174 | G28: >1 means SG&A-type costs (proxied here as Communication + Consultancy + Other expenses) grew faster than sales — disproportionate overhead growth can flag deteriorating cost discipline.
B29: TATA — Total Accruals to Total Assets | F29: =('Data-PL'!F24-'Data-CF'!D4)/'Data-BS'!F27 -> -0.039880231 | G29: Higher positive accruals (profit well above operating cash flow) can indicate more aggressive/accrual-based earnings recognition. Uses FY26 net profit and FY26 CFO (col E of Data-CF).
B30: LVGI — Leverage Index | F30: =(('Data-BS'!F40+'Data-BS'!F48)/'Data-BS'!F27)/(('Data-BS'!E40+'Data-BS'!E48)/'Data-BS'!E27) -> 1.135324 | G30: >1 means leverage (total liabilities/total assets) increased y/y — higher leverage can add pressure to meet debt covenants via aggressive accounting.
B31: M-Score = -4.84 + 0.920·DSRI + 0.528·GMI + 0.404·AQI + 0.892·SGI + 0.115·DEPI - 0.172·SGAI + 4.679·TATA - 0.327·LVGI | F31: =-4.84+0.92*F23+0.528*F24+0.404*F25+0.892*F26+0.115*F27-0.172*F28+4.679*F29-0.327*F30 -> -2.5727118 | G31: Beneish (1999) threshold: M > -1.78 flags an elevated probability of earnings manipulation; M < -1.78 suggests the company is unlikely to be a manipulator.
B32: Verdict | F32: =IF(F31>-1.78,"ELEVATED RISK — FLAGGED","LOW RISK — NOT FLAGGED") -> LOW RISK — NOT FLAGGED
B34: Interpretation: Infosys' Beneish M-Score for FY26 (vs FY25) comes out well below the -1.78 threshold, placing it in the 'unlikely to be a manipulator' range — consistent with a mature, Big-4-audited, IFRS/Ind-AS reporting company with stable margins and receivables that grow broadly in line with revenue. The main components worth watching are TATA (accruals) and DSRI (receivables growth vs. sales growth): both are modest here, reinforcing that FY26 profit growth was backed by genuine cash generation (CFO grew broadly alongside profit) rather than aggressive accrual recognition. As with the Altman score, this is a screening signal, not proof of the absence or presence of manipulation, and should be read alongside the qualitative disclosures in the annual report.

Sheet Comps - EV Multiples
A1: Comparable Company Analysis — EV/EBITDA, EV/EBIT, EV/Revenue, P/E (FY2025-26)
B3: Peer set: TCS, HCL Technologies, Wipro, Tech Mahindra — 4 comparable Indian IT-services companies. All figures ₹ Crore, FY2025-26 (year ended 31-Mar-2026), consolidated. Market data as of 11-12 Aug 2026 (NSE).
B5: A. PEER INPUT DATA (₹ Crore unless noted) — hardcoded, sourced from screener.in consolidated financials & NSE market data
B6: Line item | C6: Infosys | D6: TCS | E6: HCL Tech | F6: Wipro | G6: Tech Mahindra | H6: Source
B7: Revenue (₹ Cr) | C7: ='Data-PL'!F4 -> 178650 | D7: 267021 | E7: 130144 | F7: 92624 | G7: 56815 | H7: screener.in consolidated P&L, FY ended Mar-2026; Infosys linked to Data-PL
B8: EBIT / Operating Profit (₹ Cr) | C8: ='Data-PL'!F18+'Data-PL'!F15-'Data-PL'!F5 -> 37378 | D8: 72398 | E8: 26752 | F8: 17811 | G8: 9033 | H8: screener.in 'Operating Profit' (Sales − Expenses, i.e. EBIT) for peers; Infosys computed from Data-PL
B9: Depreciation & Amortization (₹ Cr) | C9: ='Data-PL'!F14 -> 4902 | D9: 5560 | E9: 4355 | F9: 2911 | G9: 1882 | H9: screener.in depreciation line, FY ended Mar-2026
B10: EBITDA (₹ Cr) = EBIT + D&A | C10: =C8+C9 -> 42280 | D10: =D8+D9 -> 77958 | E10: =E8+E9 -> 31107 | F10: =F8+F9 -> 20722 | G10: =G8+G9 -> 10915 | H10: Calculated
B11: Net Profit (₹ Cr) | C11: ='Data-PL'!F24 -> 29474 | D11: 49454 | E11: 16652 | F11: 13266 | G11: 4806 | H11: screener.in / company FY26 consolidated net profit
B12: Market Capitalisation (₹ Cr) | C12: =Assumptions!D48 -> 481712 | D12: 882433 | E12: 367702 | F12: 182142 | G12: 161146 | H12: NSE market cap, ~11-Aug-2026 (screener.in)
B13: Total Debt — borrowings + lease liab. (₹ Cr) | C13: ='Data-BS'!F36+'Data-BS'!F42 -> 9176 | D13: 11283 | E13: 5215 | F13: 20291 | G13: 2186 | H13: screener.in balance sheet 'Borrowings' line, FY ended Mar-2026 (includes lease liabilities)
B14: Cash & Investments (₹ Cr) | C14: ='Data-BS'!F21+'Data-BS'!F19+'Data-BS'!F11 -> 44081 | D14: 33988 | E14: 7090 | F14: 46786 | G14: 3426 | H14: screener.in balance sheet 'Investments' line (proxy for cash + near-cash + investments), FY ended Mar-2026
B15: Enterprise Value (₹ Cr) = MCap + Debt -CASH | C15: =C12+C13-C14 -> 446807 | D15: =D12+D13-D14 -> 859728 | E15: =E12+E13-E14 -> 365827 | F15: =F12+F13-F14 -> 155647 | G15: =G12+G13-G14 -> 159906 | H15: Calculated
B17: Methodology note: EV is approximated as Market Cap + Total Debt (borrowings + lease liabilities) − Cash & near-cash investments, using each company's simplified consolidated balance-sheet 'Investments' line as the cash/near-cash proxy (a standard simplification for cross-company comparability given differing balance-sheet detail levels). EBIT for peers uses screener.in's 'Operating Profit' (Sales − Expenses), which is computed pre-interest and pre-other-income, consistent with the Infosys EBIT definition used throughout this workbook.
B19: B. IMPLIED TRADING MULTIPLES
B20: Multiple | C20: Infosys | D20: TCS | E20: HCL Tech | F20: Wipro | G20: Tech Mahindra
B21: EV / EBITDA | C21: =IFERROR(C15/C10,"n.m.") -> 10.56781 | D21: =IFERROR(D15/D10,"n.m.") -> 11.028092 | E21: =IFERROR(E15/E10,"n.m.") -> 11.760279 | F21: =IFERROR(F15/F10,"n.m.") -> 7.5111958 | G21: =IFERROR(G15/G10,"n.m.") -> 14.650115
B22: EV / EBIT | C22: =IFERROR(C15/C8,"n.m.") -> 11.953743 | D22: =IFERROR(D15/D8,"n.m.") -> 11.875024 | E22: =IFERROR(E15/E8,"n.m.") -> 13.674753 | F22: =IFERROR(F15/F8,"n.m.") -> 8.7388131 | G22: =IFERROR(G15/G8,"n.m.") -> 17.702424
B23: EV / Revenue | C23: =IFERROR(C15/C7,"n.m.") -> 2.5010188 | D23: =IFERROR(D15/D7,"n.m.") -> 3.2197018 | E23: =IFERROR(E15/E7,"n.m.") -> 2.8109402 | F23: =IFERROR(F15/F7,"n.m.") -> 1.6804176 | G23: =IFERROR(G15/G7,"n.m.") -> 2.8145032
B24: P / E (Price-to-Earnings) | C24: =IFERROR(C12/C11,"n.m.") -> 16.343625 | D24: =IFERROR(D12/D11,"n.m.") -> 17.843511 | E24: =IFERROR(E12/E11,"n.m.") -> 22.081552 | F24: =IFERROR(F12/F11,"n.m.") -> 13.729986 | G24: =IFERROR(G12/G11,"n.m.") -> 33.530171
B26: C. PEER SUMMARY STATISTICS (TCS, HCL Tech, Wipro, Tech Mahindra — excludes Infosys)
B27: Multiple | C27: Mean | D27: Median | E27: Minimum | F27: Maximum | G27: Infosys (actual)
B28: EV / EBITDA | C28: =AVERAGE(D21:G21) -> 11.23742 | D28: =MEDIAN(D21:G21) -> 11.394186 | E28: =MIN(D21:G21) -> 7.5111958 | F28: =MAX(D21:G21) -> 14.650115 | G28: =C21 -> 10.56781
B29: EV / EBIT | C29: =AVERAGE(D22:G22) -> 12.997754 | D29: =MEDIAN(D22:G22) -> 12.774889 | E29: =MIN(D22:G22) -> 8.7388131 | F29: =MAX(D22:G22) -> 17.702424 | G29: =C22 -> 11.953743
B30: EV / Revenue | C30: =AVERAGE(D23:G23) -> 2.6313907 | D30: =MEDIAN(D23:G23) -> 2.8127217 | E30: =MIN(D23:G23) -> 1.6804176 | F30: =MAX(D23:G23) -> 3.2197018 | G30: =C23 -> 2.5010188
B31: P / E (Price-to-Earnings) | C31: =AVERAGE(D24:G24) -> 21.796305 | D31: =MEDIAN(D24:G24) -> 19.962531 | E31: =MIN(D24:G24) -> 13.729986 | F31: =MAX(D24:G24) -> 33.530171 | G31: =C24 -> 16.343625
B33: D. IMPLIED VALUATION OF INFOSYS (applying peer mean/median multiples to Infosys' own metrics)
B34: Basis | C34: Infosys metric (₹ Cr) | D34: Peer Mean × | E34: Implied EV / Equity (₹ Cr, Mean) | F34: Peer Median × | G34: Implied EV / Equity (₹ Cr, Median) | H34: Per-share (₹, Mean basis)
B35: EV / EBITDA basis (Infosys EBITDA) | C35: =C10 -> 42280 | D35: =C28 -> 11.23742 | E35: =C35*D35 -> 475118.13 | F35: =D28 -> 11.394186 | G35: =C35*F35 -> 481746.16 | H35: =(E35-C13+C14)/Assumptions!$D$47 -> 1259.9386
B36: EV / EBIT basis (Infosys EBIT) | C36: =C8 -> 37378 | D36: =C29 -> 12.997754 | E36: =C36*D36 -> 485830.04 | F36: =D29 -> 12.774889 | G36: =C36*F36 -> 477499.79 | H36: =(E36-C13+C14)/Assumptions!$D$47 -> 1286.4008
B37: EV / Revenue basis (Infosys Revenue) | C37: =C7 -> 178650 | D37: =C30 -> 2.6313907 | E37: =C37*D37 -> 470097.95 | F37: =D30 -> 2.8127217 | G37: =C37*F37 -> 502492.73 | H37: =(E37-C13+C14)/Assumptions!$D$47 -> 1247.5369
B38: P/E basis (Infosys Net Profit) — direct equity value | C38: =C11 -> 29474 | D38: =C31 -> 21.796305 | E38: =C38*D38 -> 642424.29 | F38: =D31 -> 19.962531 | G38: =C38*F38 -> 588375.65 | H38: =E38/Assumptions!$D$47 -> 1587.0165
B40: Average implied value per share across the 4 methods (Mean-multiple basis) | H40: =AVERAGE(H36:H39) -> 1373.6514
B41: Current market price (₹, Aug-2026) & implied upside/(downside) | G41: =Assumptions!$D$46 -> 1190 | H41: =H40/G41-1 -> 0.15432892
B43: Observations:
B44: • Infosys trades at a discount to peer-average multiples on EV/EBITDA and EV/EBIT — largely reflecting TCS's premium rating (scale, margins) and the broader FY26 de-rating across Indian IT stocks amid AI-disruption concerns, rather than an Infosys-specific fundamental weakness (its own margins and returns are competitive within the peer set — see Ratio Analysis).
B45: • Tech Mahindra's elevated EV/EBITDA and P/E multiples reflect its smaller earnings base and post-turnaround re-rating rather than superior fundamentals — a useful reminder to sense-check outlier multiples rather than apply mean/median mechanically.
B46: • The comparable-company approach and the DCF (see DCF Valuation sheet) should be read together: DCF captures Infosys-specific growth and margin trajectory, while the comps approach captures how the market is currently pricing the sector — convergence or divergence between the two is itself an important finding for the report.

Sheet Ratio - Cover & Notes
B2: INFOSYS LIMITED - FINANCIAL RATIO ANALYSIS
B3: Financial Statement Analysis & Valuation (FSAV) Project - incl. Peer Comparison vs TCS & HCLTech
B5: Company | C5: Infosys Limited (NSE: INFY, BSE: 500209, NYSE ADR: INFY) - Peers: Tata Consultancy Services (TCS) and HCL Technologies (HCLTech)
B7: Basis of figures | C7: Consolidated financial statements as reported by each company (Infosys & TCS: IFRS; HCLTech: Ind AS) for FY 2025-26 (year ended 31 March 2026). Figures in Rs. Crore unless stated as per-share data.
B9: Market price used | C9: NSE closing prices, 6-Aug-2026 (same source/date for all three companies, for comparability): Infosys Rs. 1,165.00 · TCS Rs. 2,373.00 · HCLTech Rs. 1,335.00
B11: Primary sources - Infosys | C11: Infosys IR - Three-Year Overview (IFRS, Consolidated INR Basis): P&L Data & Balance Sheet Data, infosys.com/investors/reports-filings/financials/ ; Infosys Q4/FY26 IFRS-INR results, 23-Apr-2026; dividend announcements
B13: Primary sources - TCS | C13: TCS Integrated Annual Report 2025-26 - Consolidated Balance Sheet & Consolidated Statement of Profit and Loss (as uploaded), and the Directors' Report dividend table
B15: Primary sources - HCLTech | C15: HCLTech Integrated Annual Report 2025-26 - Consolidated Balance Sheet & Consolidated Statement of Profit and Loss (as uploaded), Note 3.27 (EPS), and the Directors' Report dividend table
B17: Key methodology notes | C17: 1) Infosys and TCS carry no material inventory beyond token amounts; HCLTech's inventory (mainly hardware/stock-in-trade) is small relative to revenue - all three are people-driven services businesses, so Quick Ratio is close to the Current Ratio for each. 2) None of the three companies carries material long-term financial borrowings; 'Total Debt' used in the Debt-Equity Ratio is predominantly lease liabilities recognised under Ind AS 116 / IFRS 16 (plus token working-capital borrowings for HCLTech). 3) Operating Profit (EBIT) for TCS and HCLTech is derived as Revenue from Operations − Total Operating Expenses excluding Finance Costs, Other Income and Exceptional Items - the same concept as Infosys's directly-disclosed 'Operating Profit' line, so the three are comparable. 4) Debtors = billed Trade Receivables (excludes unbilled revenue, shown separately by all three companies). 5) Debt Service Coverage Ratio = (Net Profit + Interest + Depreciation) ÷ (Interest + Current portion of lease liabilities/borrowings) - a reasonable proxy given none of the three has conventional term loans with fixed repayment schedules. 6) Net Profit Margin, ROA and ROE use Net Profit before minority-interest split (i.e. consolidated Profit for the Year) over Total Assets / Total Equity (both inclusive of non-controlling interests) for a like-for-like basis across all three companies. 7) Dividend Per Share: Infosys and TCS = interim(s) + final dividend declared for FY26; HCLTech pays only interim dividends through the year (no final) — the Rs. 54/share figure used is dividends actually paid during FY 2025-26 per its Directors' Report; a further Rs. 24/share interim was declared in April 2026 but is explicitly attributed by HCLTech to FY 2026-27.
B19: How this workbook is organised | C19: 'Input Data' holds Infosys's raw figures with sources. 'Ratio Analysis' computes Infosys's 19 ratios with live formulas, formula text, and interpretation. 'Peer Comparison' places Infosys, TCS and HCLTech side-by-side for FY 2025-26 across the same ratio set.

Sheet Input Data
A1: INFOSYS LIMITED — INPUT DATA (Consolidated, IFRS, Rs. Crore unless stated)
A3: Line Item | B3: Unit | C3: FY 2025-26 (Year ended 31-Mar-2026) | D3: FY 2024-25 (Year ended 31-Mar-2025) | E3: Source
A4: INCOME STATEMENT
A5: Revenue from Operations | B5: Rs. Cr | C5: 178650 | D5: 162990 | E5: Infosys IR Three-Year Overview (IFRS): P&L Data, infosys.com/investors/reports-filings/financials/profit-loss-data.html
A6: Cost of Sales | B6: Rs. Cr | C6: 124735 | D6: 113347 | E6: Infosys IR - Three-Year Overview (IFRS): P&L Data, infosys.com/investors/reports-filings/financials/profit-loss-data.html
A7: Gross Profit | B7: Rs. Cr | C7: =C5-C6 -> 53915 | D7: =D5-D6 -> 49643 | E7: Calculated from rows above in this sheet (see formula in cell)
A8: Total Operating Expenses (S&M + Admin) | B8: Rs. Cr | C8: 17661 | D8: 15219 | E8: Infosys IR - Three-Year Overview (IFRS): P&L Data, infosys.com/investors/reports-filings/financials/profit-loss-data.html
A9: Operating Profit (EBIT) | B9: Rs. Cr | C9: 36254 | D9: 34424 | E9: Infosys IR - Three-Year Overview (IFRS): P&L Data, infosys.com/investors/reports-filings/financials/profit-loss-data.html
A10: Other Income | B10: Rs. Cr | C10: 4157 | D10: 3600 | E10: Infosys IR - Three-Year Overview (IFRS): P&L Data, infosys.com/investors/reports-filings/financials/profit-loss-data.html
A11: Finance Cost (Interest Expense) | B11: Rs. Cr | C11: 416 | D11: 416 | E11: Infosys IR - Three-Year Overview (IFRS): P&L Data, infosys.com/investors/reports-filings/financials/profit-loss-data.html
A12: Profit Before Tax (PBT) | B12: Rs. Cr | C12: 39995 | D12: 37608 | E12: Infosys IR - Three-Year Overview (IFRS): P&L Data, infosys.com/investors/reports-filings/financials/profit-loss-data.html
A13: Income Tax Expense | B13: Rs. Cr | C13: 10521 | D13: 10858 | E13: Infosys IR - Three-Year Overview (IFRS): P&L Data, infosys.com/investors/reports-filings/financials/profit-loss-data.html
A14: Net Profit (Consolidated) | B14: Rs. Cr | C14: 29474 | D14: 26750 | E14: Infosys IR - Three-Year Overview (IFRS): P&L Data, infosys.com/investors/reports-filings/financials/profit-loss-data.html
A15: Net Profit attributable to Owners of the Company | B15: Rs. Cr | C15: 29440 | D15: 26713 | E15: Infosys IR - Three-Year Overview (IFRS): P&L Data, infosys.com/investors/reports-filings/financials/profit-loss-data.html
A17: BALANCE SHEET
A18: Total Assets | B18: Rs. Cr | C18: 155967 | D18: 148903 | E18: Infosys IR - Three-Year Overview (IFRS): Balance Sheet Data, infosys.com/investors/reports-filings/financials/balance-sheet-data.html
